Workbook

Sheet Summary
A5: Fecha | B5: P&L MWh | C5: US$ / MWh | D5: P&L US$ | E5: Observación
A6: 45962 | B6: ='2025_11_01'!$B$12 -> -0.026711524 | C6: ='2025_11_01'!$B$13 -> 80 | D6: ='2025_11_01'!$B$14 -> -2.1369219
A7: 45963 | B7: ='2025_11_02'!B12 -> -0.017181413 | C7: ='2025_11_02'!B13 -> 80 | D7: ='2025_11_02'!B14 -> -1.374513
A8: 45964 | B8: ='2025_11_03'!$B$12 -> 0.0038664304 | C8: ='2025_11_03'!$B$13 -> 80 | D8: ='2025_11_03'!$B$14 -> 0.30931443
A9: 45965 | B9: ='2025_11_04'!$B$12 -> 0.044131075 | C9: ='2025_11_04'!$B$13 -> 80 | D9: ='2025_11_04'!$B$14 -> 3.530486
A10: 45966 | B10: ='2025_11_05'!B12 -> 0.051092311 | C10: ='2025_11_05'!B13 -> 80 | D10: ='2025_11_05'!B14 -> 4.0873849
A11: 45967 | B11: ='2025_11_06'!B12 -> -0.017003184 | C11: ='2025_11_06'!B13 -> 80 | D11: ='2025_11_06'!B14 -> -1.3602547
A12: 45968
A13: 45969
A14: 45970
A15: 45971
A16: 45972
A17: 45973
A18: 45974
A19: 45975
A20: 45976
A21: 45977
A22: 45978
A23: 45979
... A35: 45991

Sheet 2025_11_01
A3: FECHA | B3: GENERADORA | C3: 0.30972222 | J3: 0.31875 | Q3: 0.32222222 | X3: 0.32569444 | AE3: 0.32777778 | AL3: 0.34444444 | AS3: 0.34791667 | AZ3: 0.35277778 | BG3: 0.41875 | BN3: 0.43888889 | BU3: 0.49791667 | CB3: 0.50902778 | CI3: 0.52152778 | CP3: 0.56388889 | CW3: 0.63333333 | DD3: 0.70277778 | DK3: 0.70902778 | DR3: 0.72361111 | DY3: 0.79097222 | EF3: 0.79513889 | EM3: 0.79722222
C4: POTENCIA ACTIVA (MW) | D4: AUMENTO / DISMINUCION REAL (MW) | E4: NUEVO SET POINT POTENCIA ACTIVA (MW) | F4: % DEL AUMENTO / DISMINUCION DEL TOTAL | G4: % DE AUMENTO / DISMINUCION IDEAL | H4: % DIFERENCIA | I4: AUMENTO / DISMINUCION IDEAL (MW) | J4: POTENCIA ACTIVA (MW) | K4: AUMENTO / DISMINUCION REAL (MW) | L4: NUEVO SET POINT POTENCIA ACTIVA (MW) | M4: % DEL AUMENTO / DISMINUCION DEL TOTAL | N4: % DE AUMENTO / DISMINUCION IDEAL | O4: % DIFERENCIA | P4: AUMENTO / DISMINUCION IDEAL (MW) | Q4: POTENCIA ACTIVA (MW) | R4: AUMENTO / DISMINUCION REAL (MW) | S4: NUEVO SET POINT POTENCIA ACTIVA (MW) | T4: % DEL AUMENTO / DISMINUCION DEL TOTAL | U4: % DE AUMENTO / DISMINUCION IDEAL | V4: % DIFERENCIA | W4: AUMENTO / DISMINUCION IDEAL (MW) | X4: POTENCIA ACTIVA (MW) | Y4: AUMENTO / DISMINUCION REAL (MW) | Z4: NUEVO SET POINT POTENCIA ACTIVA (MW) | AA4: % DEL AUMENTO / DISMINUCION DEL TOTAL | AB4: % DE AUMENTO / DISMINUCION IDEAL | AC4: % DIFERENCIA | AD4: AUMENTO / DISMINUCION IDEAL (MW) | AE4: POTENCIA ACTIVA (MW) | AF4: AUMENTO / DISMINUCION REAL (MW) | AG4: NUEVO SET POINT POTENCIA ACTIVA (MW) | AH4: % DEL AUMENTO / DISMINUCION DEL TOTAL | AI4: % DE AUMENTO / DISMINUCION IDEAL | AJ4: % DIFERENCIA | AK4: AUMENTO / DISMINUCION IDEAL (MW) | AL4: POTENCIA ACTIVA (MW) | AM4: AUMENTO / DISMINUCION REAL (MW) | AN4: NUEVO SET POINT POTENCIA ACTIVA (MW) | AO4: % DEL AUMENTO / DISMINUCION DEL TOTAL | AP4: % DE AUMENTO / DISMINUCION IDEAL | AQ4: % DIFERENCIA | AR4: AUMENTO / DISMINUCION IDEAL (MW) | AS4: POTENCIA ACTIVA (MW) | AT4: AUMENTO / DISMINUCION REAL (MW) | AU4: NUEVO SET POINT POTENCIA ACTIVA (MW) | AV4: % DEL AUMENTO / DISMINUCION DEL TOTAL | AW4: % DE AUMENTO / DISMINUCION IDEAL | AX4: % DIFERENCIA | AY4: AUMENTO / DISMINUCION IDEAL (MW) | AZ4: POTENCIA ACTIVA (MW) | BA4: AUMENTO / DISMINUCION REAL (MW) | BB4: NUEVO SET POINT POTENCIA ACTIVA (MW) | BC4: % DEL AUMENTO / DISMINUCION DEL TOTAL | BD4: % DE AUMENTO / DISMINUCION IDEAL | BE4: % DIFERENCIA | BF4: AUMENTO / DISMINUCION IDEAL (MW) | BG4: GEN.ACTUAL | BH4: MONTO | BI4: CONSIGNA | BJ4: % DEL AUMENTO / DISMINUCION DEL TOTAL | BK4: % DE AUMENTO / DISMINUCION IDEAL | BL4: % DIFERENCIA | BM4: AUMENTO / DISMINUCION IDEAL (MW) | BN4: GEN.ACTUAL | BO4: MONTO | BP4: CONSIGNA | BQ4: % DEL AUMENTO / DISMINUCION DEL TOTAL | BR4: % DE AUMENTO / DISMINUCION IDEAL | BS4: % DIFERENCIA | BT4: AUMENTO / DISMINUCION IDEAL (MW) | BU4: GEN.ACTUAL | BV4: MONTO | BW4: CONSIGNA | BX4: % DEL AUMENTO / DISMINUCION DEL TOTAL | BY4: % DE AUMENTO / DISMINUCION IDEAL | BZ4: % DIFERENCIA | CA4: AUMENTO / DISMINUCION IDEAL (MW) | CB4: GEN.ACTUAL | CC4: MONTO | CD4: CONSIGNA | CE4: % DEL AUMENTO / DISMINUCION DEL TOTAL | CF4: % DE AUMENTO / DISMINUCION IDEAL | CG4: % DIFERENCIA | CH4: AUMENTO / DISMINUCION IDEAL (MW) | CI4: GEN.ACTUAL | CJ4: MONTO | CK4: CONSIGNA | CL4: % DEL AUMENTO / DISMINUCION DEL TOTAL | CM4: % DE AUMENTO / DISMINUCION IDEAL | CN4: % DIFERENCIA | CO4: AUMENTO / DISMINUCION IDEAL (MW) | CP4: GEN.ACTUAL | CQ4: MONTO | CR4: CONSIGNA | CS4: % DEL AUMENTO / DISMINUCION DEL TOTAL | CT4: % DE AUMENTO / DISMINUCION IDEAL | CU4: % DIFERENCIA | CV4: AUMENTO / DISMINUCION IDEAL (MW) | CW4: GEN.ACTUAL | CX4: MONTO | CY4: CONSIGNA | CZ4: % DEL AUMENTO / DISMINUCION DEL TOTAL | DA4: % DE AUMENTO / DISMINUCION IDEAL | DB4: % DIFERENCIA | DC4: AUMENTO / DISMINUCION IDEAL (MW) | DD4: GEN.ACTUAL | DE4: MONTO | DF4: CONSIGNA | DG4: % DEL AUMENTO / DISMINUCION DEL TOTAL | DH4: % DE AUMENTO / DISMINUCION IDEAL | DI4: % DIFERENCIA | DJ4: AUMENTO / DISMINUCION IDEAL (MW) | DK4: GEN.ACTUAL | DL4: MONTO | DM4: CONSIGNA | DN4: % DEL AUMENTO / DISMINUCION DEL TOTAL | DO4: % DE AUMENTO / DISMINUCION IDEAL | DP4: % DIFERENCIA | DQ4: AUMENTO / DISMINUCION IDEAL (MW) | DR4: GEN.ACTUAL | DS4: MONTO | DT4: CONSIGNA | DU4: % DEL AUMENTO / DISMINUCION DEL TOTAL | DV4: % DE AUMENTO / DISMINUCION IDEAL | DW4: % DIFERENCIA | DX4: AUMENTO / DISMINUCION IDEAL (MW) | DY4: GEN.ACTUAL | DZ4: MONTO | EA4: CONSIGNA | EB4: % DEL AUMENTO / DISMINUCION DEL TOTAL | EC4: % DE AUMENTO / DISMINUCION IDEAL | ED4: % DIFERENCIA | EE4: AUMENTO / DISMINUCION IDEAL (MW) | EF4: GEN.ACTUAL | EG4: MONTO | EH4: CONSIGNA | EI4: % DEL AUMENTO / DISMINUCION DEL TOTAL | EJ4: % DE AUMENTO / DISMINUCION IDEAL | EK4: % DIFERENCIA | EL4: AUMENTO / DISMINUCION IDEAL (MW) | EM4: GEN.ACTUAL | EN4: MONTO | EO4: CONSIGNA | EP4: % DEL AUMENTO / DISMINUCION DEL TOTAL | EQ4: % DE AUMENTO / DISMINUCION IDEAL | ER4: % DIFERENCIA | ES4: AUMENTO / DISMINUCION IDEAL (MW)
A5: 45962 | B5: PFV-ELPELICANO | C5: 14 | D5: 0 | E5: 13.5 | F5: =IF($D$8=0,0,D5/$D$8) -> 0 | G5: =C16 -> 0.27202073 | H5: =F5-G5 -> -0.27202073 | I5: =G5*$D$8 -> 0 | J5: 14 | K5: 14 | L5: 28.5 | M5: =IF($K$8=0,0,J5/$K$8) -> 0.4 | N5: =C16 -> 0.27202073 | O5: =M5-N5 -> 0.12797927 | P5: =N5*$K$8 -> 9.5207254 | Q5: 29 | R5: -5 | S5: 24.4 | T5: =R5/$R$8 -> -0.5 | U5: =C16 -> 0.27202073 | V5: =T5-U5 -> -0.77202073 | W5: =U5*$R$8 -> 2.7202073 | X5: 29 | Y5: -8 | Z5: 20.7 | AA5: =Y5/Y8 -> 1.1428571 | AB5: =C16 -> 0.27202073 | AC5: =AA5-AB5 -> 0.87083642 | AD5: =AB5*Y8 -> -1.9041451 | AE5: 21 | AF5: -5 | AG5: 15.3 | AH5: =AF5/$AF$8 -> 0.71428571 | AI5: =C16 -> 0.27202073 | AJ5: =AH5-AI5 -> 0.44226499 | AK5: =AI5*$AF$8 -> -1.9041451 | AL5: 15 | AM5: 1 | AN5: 16.2 | AO5: =AM5/$AM$8 -> 0.25 | AP5: =C16 -> 0.27202073 | AQ5: =AO5-AP5 -> -0.022020725 | AR5: =AP5*$AM$8 -> 1.0880829 | AS5: 15 | AT5: 4 | AU5: 19.2 | AV5: =AT5/$AT$8 -> 0.28571429 | AW5: =C16 -> 0.27202073 | AX5: =AV5-AW5 -> 0.01369356 | AY5: =AW5*$AT$8 -> 3.8082902 | AZ5: 21 | BA5: 3 | BB5: 23.9 | BC5: =BA5/$BA$8 -> 0.13636364 | BD5: =C16 -> 0.27202073 | BE5: =BC5-BD5 -> -0.13565709 | BF5: =BD5*$BA$8 -> 5.984456 | BG5: 24 | BH5: 11 | BI5: 35.3 | BJ5: =BH5/$BH$8 -> -0.21153846 | BK5: =C16 -> 0.27202073 | BL5: =BJ5-BK5 -> -0.48355919 | BM5: =BK5*$BH$8 -> -14.145078 | BN5: 35 | BO5: 3 | BP5: 38.3 | BQ5: =BO5/$BO$8 -> -0.16666667 | BR5: =C16 -> 0.27202073 | BS5: =BQ5-BR5 -> -0.43868739 | BT5: =BR5*$BO$8 -> -4.8963731 | BU5: 38 | BV5: -8 | BW5: 30 | BX5: =BV5/$BV$8 -> 1.3333333 | BY5: =C16 -> 0.27202073 | BZ5: =BX5-BY5 -> 1.0613126 | CA5: =BY5*$BV$8 -> -1.6321244 | CB5: 30 | CC5: 0 | CD5: 29.9 | CE5: =CC5/$CC$8 -> 0 | CF5: =C16 -> 0.27202073 | CG5: =CE5-CF5 -> -0.27202073 | CH5: =CF5*$CC$8 -> -14.417098 | CI5: 30 | CJ5: 1 | CK5: 30.7 | CL5: =CJ5/$CJ$8 -> -0.03030303 | CM5: =C16 -> 0.27202073 | CN5: =CL5-CM5 -> -0.30232376 | CO5: =CM5*$CJ$8 -> -8.9766839 | CP5: 31 | CQ5: 2 | CR5: 33.2 | CS5: =CQ5/$CQ$8 -> -0.058823529 | CT5: =C16 -> 0.27202073 | CU5: =CS5-CT5 -> -0.33084425 | CV5: =CT5*$CQ$8 -> -9.2487047 | CW5: 33 | CX5: -6 | CY5: 26.6 | CZ5: =CX5/$CX$8 -> -0.75 | DA5: =C16 -> 0.27202073 | DB5: =CZ5-DA5 -> -1.0220207 | DC5: =DA5*$CX$8 -> 2.1761658 | DD5: 27 | DE5: -2 | DF5: 24.6 | DG5: =DE5/$DE$8 -> 0.052631579 | DH5: =C16 -> 0.27202073 | DI5: =DG5-DH5 -> -0.21938915 | DJ5: =DH5*$DE$8 -> -10.336788 | DK5: 25 | DL5: -3 | DM5: 22.2 | DN5: =DL5/$DL$8 -> 0.33333333 | DO5: =C16 -> 0.27202073 | DP5: =DN5-DO5 -> 0.061312608 | DQ5: =DO5*$DL$8 -> -2.4481865 | DR5: 22 | DS5: 5 | DT5: 27.3 | DU5: =DS5/$DS$8 -> 0.38461538 | DV5: =C16 -> 0.27202073 | DW5: =DU5-DV5 -> 0.11259466 | DX5: =DV5*$DS$8 -> 3.5362694 | DY5: 27 | DZ5: 6 | EA5: 32.6 | EB5: =DZ5/$DZ$8 -> 0.375 | EC5: =C16 -> 0.27202073 | ED5: =EB5-EC5 -> 0.10297927 | EE5: =EC5*$DZ$8 -> 4.3523316 | EF5: 27 | EG5: 8 | EH5: 34.9 | EI5: =EG5/$EG$8 -> 0.47058824 | EJ5: =C16 -> 0.27202073 | EK5: =EI5-EJ5 -> 0.19856751 | EL5: =EJ5*$EG$8 -> 4.6243523 | EM5: 27 | EN5: 6 | EO5: 33 | EP5: =EN5/$EN$8 -> 0.4 | EQ5: =C16 -> 0.27202073 | ER5: =EP5-EQ5 -> 0.12797927 | ES5: =EQ5*$EN$8 -> 4.0803109
A6: 45962 | B6: PFV-ELROMERO | C6: 6 | D6: 0 | E6: 5.6 | F6: =IF($D$8=0,0,D6/$D$8) -> 0 | G6: =C17 -> 0.50777202 | H6: =F6-G6 -> -0.50777202 | I6: =G6*$D$8 -> 0 | J6: 13 | K6: 8 | L6: 21 | M6: =IF($K$8=0,0,J6/$K$8) -> 0.37142857 | N6: =C17 -> 0.50777202 | O6: =M6-N6 -> -0.13634345 | P6: =N6*$D$8 -> 0 | Q6: 16 | R6: 9 | S6: 25.2 | T6: =R6/$R$8 -> 0.9 | U6: =C17 -> 0.50777202 | V6: =T6-U6 -> 0.39222798 | W6: =U6*$R$8 -> 5.0777202 | X6: 20 | Y6: 8 | Z6: 27.8 | AA6: =Y6/$Y$8 -> -1.1428571 | AB6: =C17 -> 0.50777202 | AC6: =AA6-AB6 -> -1.6506292 | AD6: =AB6*$Y$8 -> -3.5544041 | AE6: 23 | AF6: 5 | AG6: 27.7 | AH6: =AF6/$AF$8 -> -0.71428571 | AI6: =C17 -> 0.50777202 | AJ6: =AH6-AI6 -> -1.2220577 | AK6: =AI6*$AF$8 -> -3.5544041 | AL6: 28 | AM6: 2 | AN6: 29.3 | AO6: =AM6/$AM$8 -> 0.5 | AP6: =C17 -> 0.50777202 | AQ6: =AO6-AP6 -> -0.0077720207 | AR6: =AP6*$AM$8 -> 2.0310881 | AS6: 28 | AT6: 7 | AU6: 34.9 | AV6: =AT6/$AT$8 -> 0.5 | AW6: =C17 -> 0.50777202 | AX6: =AV6-AW6 -> -0.0077720207 | AY6: =AW6*$AT$8 -> 7.1088083 | AZ6: 28 | BA6: 15 | BB6: 43.3 | BC6: =BA6/$BA$8 -> 0.68181818 | BD6: =C17 -> 0.50777202 | BE6: =BC6-BD6 -> 0.17404616 | BF6: =BD6*$BA$8 -> 11.170984 | BG6: 136 | BH6: -72 | BI6: 64 | BJ6: =BH6/$BH$8 -> 1.3846154 | BK6: =C17 -> 0.50777202 | BL6: =BJ6-BK6 -> 0.87684336 | BM6: =BK6*$BH$8 -> -26.404145 | BN6: 92 | BO6: -23 | BP6: 69.3 | BQ6: =BO6/$BO$8 -> 1.2777778 | BR6: =C17 -> 0.50777202 | BS6: =BQ6-BR6 -> 0.77000576 | BT6: =BR6*$BO$8 -> -9.1398964 | BU6: 68 | BV6: 8 | BW6: 76.4 | BX6: =BV6/$BV$8 -> -1.3333333 | BY6: =C17 -> 0.50777202 | BZ6: =BX6-BY6 -> -1.8411054 | CA6: =BY6*$BV$8 -> -3.0466321 | CB6: 128 | CC6: -52 | CD6: 76.4 | CE6: =CC6/$CC$8 -> 0.98113208 | CF6: =C17 -> 0.50777202 | CG6: =CE6-CF6 -> 0.47336005 | CH6: =CF6*$CC$8 -> -26.911917 | CI6: 110 | CJ6: -34 | CK6: 76.4 | CL6: =CJ6/$CJ$8 -> 1.030303 | CM6: =C17 -> 0.50777202 | CN6: =CL6-CM6 -> 0.52253101 | CO6: =CM6*$CJ$8 -> -16.756477 | CP6: 115 | CQ6: -38 | CR6: 76.4 | CS6: =CQ6/$CQ$8 -> 1.1176471 | CT6: =C17 -> 0.50777202 | CU6: =CS6-CT6 -> 0.60987504 | CV6: =CT6*$CQ$8 -> -17.264249 | CW6: 60 | CX6: 19 | CY6: 78.6 | CZ6: =CX6/$CX$8 -> 2.375 | DA6: =C17 -> 0.50777202 | DB6: =CZ6-DA6 -> 1.867228 | DC6: =DA6*$CX$8 -> 4.0621762 | DD6: 78 | DE6: -34 | DF6: 44.7 | DG6: =DE6/$DE$8 -> 0.89473684 | DH6: =C17 -> 0.50777202 | DI6: =DG6-DH6 -> 0.38696482 | DJ6: =DH6*$DE$8 -> -19.295337 | DK6: 45 | DL6: -4 | DM6: 40.3 | DN6: =DL6/$DL$8 -> 0.44444444 | DO6: =C17 -> 0.50777202 | DP6: =DN6-DO6 -> -0.063327576 | DQ6: =DO6*$DL$8 -> -4.5699482 | DR6: 45 | DS6: 5 | DT6: 49.4 | DU6: =DS6/$DS$8 -> 0.38461538 | DV6: =C17 -> 0.50777202 | DW6: =DU6-DV6 -> -0.12315664 | DX6: =DV6*$DS$8 -> 6.6010363 | DY6: 18 | DZ6: 5 | EA6: 22.3 | EB6: =DZ6/$DZ$8 -> 0.3125 | EC6: =C17 -> 0.50777202 | ED6: =EB6-EC6 -> -0.19527202 | EE6: =EC6*$DZ$8 -> 8.1243523 | EF6: 13 | EG6: 5 | EH6: 18 | EI6: =EG6/$EG$8 -> 0.29411765 | EJ6: =C17 -> 0.50777202 | EK6: =EI6-EJ6 -> -0.21365437 | EL6: =EJ6*$EG$8 -> 8.6321244 | EM6: 12 | EN6: 5 | EO6: 16.3 | EP6: =EN6/$EN$8 -> 0.33333333 | EQ6: =C17 -> 0.50777202 | ER6: =EP6-EQ6 -> -0.17443869 | ES6: =EQ6*$EN$8 -> 7.6165803
A7: 45962 | B7: PFV-LAHUELLA | C7: 10 | D7: 0 | E7: 9.9 | F7: =IF($D$8=0,0,D7/$D$8) -> 0 | G7: =C18 -> 0.22020725 | H7: =F7-G7 -> -0.22020725 | I7: =G7*$D$8 -> 0 | J7: 10 | K7: 13 | L7: 22.9 | M7: =IF($K$8=0,0,J7/$K$8) -> 0.28571429 | N7: =C18 -> 0.22020725 | O7: =M7-N7 -> 0.065507032 | P7: =N7*$D$8 -> 0 | Q7: 13 | R7: 6 | S7: 19.2 | T7: =R7/$R$8 -> 0.6 | U7: =C18 -> 0.22020725 | V7: =T7-U7 -> 0.37979275 | W7: =U7*$R$8 -> 2.2020725 | X7: 23 | Y7: -7 | Z7: 16.3 | AA7: =Y7/$Y$8 -> 1 | AB7: =C18 -> 0.22020725 | AC7: =AA7-AB7 -> 0.77979275 | AD7: =AB7*$Y$8 -> -1.5414508 | AE7: 19 | AF7: -7 | AG7: 12 | AH7: =AF7/$AF$8 -> 1 | AI7: =C18 -> 0.22020725 | AJ7: =AH7-AI7 -> 0.77979275 | AK7: =AI7*$AF$8 -> -1.5414508 | AL7: 12 | AM7: 1 | AN7: 12.7 | AO7: =AM7/$AM$8 -> 0.25 | AP7: =C18 -> 0.22020725 | AQ7: =AO7-AP7 -> 0.029792746 | AR7: =AP7*$AM$8 -> 0.88082902 | AS7: 12 | AT7: 3 | AU7: 15.1 | AV7: =AT7/$AT$8 -> 0.21428571 | AW7: =C18 -> 0.22020725 | AX7: =AV7-AW7 -> -0.0059215396 | AY7: =AW7*$AT$8 -> 3.0829016 | AZ7: 15 | BA7: 4 | BB7: 18.8 | BC7: =BA7/$BA$8 -> 0.18181818 | BD7: =C18 -> 0.22020725 | BE7: =BC7-BD7 -> -0.038389072 | BF7: =BD7*$BA$8 -> 4.8445596 | BG7: 19 | BH7: 9 | BI7: 27.7 | BJ7: =BH7/$BH$8 -> -0.17307692 | BK7: =C18 -> 0.22020725 | BL7: =BJ7-BK7 -> -0.39328418 | BM7: =BK7*$BH$8 -> -11.450777 | BN7: 28 | BO7: 2 | BP7: 30.1 | BQ7: =BO7/$BO$8 -> -0.11111111 | BR7: =C18 -> 0.22020725 | BS7: =BQ7-BR7 -> -0.33131836 | BT7: =BR7*$BO$8 -> -3.9637306 | BU7: 30 | BV7: -6 | BW7: 23.6 | BX7: =BV7/$BV$8 -> 1 | BY7: =C18 -> 0.22020725 | BZ7: =BX7-BY7 -> 0.77979275 | CA7: =BY7*$BV$8 -> -1.3212435 | CB7: 24 | CC7: -1 | CD7: 23.5 | CE7: =CC7/$CC$8 -> 0.018867925 | CF7: =C18 -> 0.22020725 | CG7: =CE7-CF7 -> -0.20133933 | CH7: =CF7*$CC$8 -> -11.670984 | CI7: 24 | CJ7: 0 | CK7: 24.2 | CL7: =CJ7/$CJ$8 -> 0 | CM7: =C18 -> 0.22020725 | CN7: =CL7-CM7 -> -0.22020725 | CO7: =CM7*$CJ$8 -> -7.2668394 | CP7: 24 | CQ7: 2 | CR7: 26.1 | CS7: =CQ7/$CQ$8 -> -0.058823529 | CT7: =C18 -> 0.22020725 | CU7: =CS7-CT7 -> -0.27903078 | CV7: =CT7*$CQ$8 -> -7.4870466 | CW7: 26 | CX7: -5 | CY7: 20.9 | CZ7: =CX7/$CX$8 -> -0.625 | DA7: =C18 -> 0.22020725 | DB7: =CZ7-DA7 -> -0.84520725 | DC7: =DA7*$CX$8 -> 1.761658 | DD7: 21 | DE7: -2 | DF7: 19.4 | DG7: =DE7/$DE$8 -> 0.052631579 | DH7: =C18 -> 0.22020725 | DI7: =DG7-DH7 -> -0.16757567 | DJ7: =DH7*$DE$8 -> -8.3678756 | DK7: 19 | DL7: -2 | DM7: 17.5 | DN7: =DL7/$DL$8 -> 0.22222222 | DO7: =C18 -> 0.22020725 | DP7: =DN7-DO7 -> 0.0020149683 | DQ7: =DO7*$DL$8 -> -1.9818653 | DR7: 18 | DS7: 3 | DT7: 21.4 | DU7: =DS7/$DS$8 -> 0.23076923 | DV7: =C18 -> 0.22020725 | DW7: =DU7-DV7 -> 0.010561977 | DX7: =DV7*$DS$8 -> 2.8626943 | DY7: 21 | DZ7: 5 | EA7: 25.6 | EB7: =DZ7/$DZ$8 -> 0.3125 | EC7: =C18 -> 0.22020725 | ED7: =EB7-EC7 -> 0.092292746 | EE7: =EC7*$DZ$8 -> 3.5233161 | EF7: 25 | EG7: 4 | EH7: 29.3 | EI7: =EG7/$EG$8 -> 0.23529412 | EJ7: =C18 -> 0.22020725 | EK7: =EI7-EJ7 -> 0.015086864 | EL7: =EJ7*$EG$8 -> 3.7435233 | EM7: 24 | EN7: 4 | EO7: 27.4 | EP7: =EN7/$EN$8 -> 0.26666667 | EQ7: =C18 -> 0.22020725 | ER7: =EP7-EQ7 -> 0.046459413 | ES7: =EQ7*$EN$8 -> 3.3031088
D8: =SUM(D5:D7) -> 0 | I8: =SUM(I5:I7) -> 0 | K8: =SUM(K5:K7) -> 35 | P8: =SUM(P5:P7) -> 9.5207254 | R8: =SUM(R5:R7) -> 10 | W8: =SUM(W5:W7) -> 10 | Y8: =SUM(Y5:Y7) -> -7 | AD8: =SUM(AD5:AD7) -> -7 | AF8: =SUM(AF5:AF7) -> -7 | AK8: =SUM(AK5:AK7) -> -7 | AM8: =SUM(AM5:AM7) -> 4 | AR8: =SUM(AR5:AR7) -> 4 | AT8: =SUM(AT5:AT7) -> 14 | AY8: =SUM(AY5:AY7) -> 14 | BA8: =SUM(BA5:BA7) -> 22 | BF8: =SUM(BF5:BF7) -> 22 | BH8: =SUM(BH5:BH7) -> -52 | BM8: =SUM(BM5:BM7) -> -52 | BO8: =SUM(BO5:BO7) -> -18 | BT8: =SUM(BT5:BT7) -> -18 | BV8: =SUM(BV5:BV7) -> -6 | CA8: =SUM(CA5:CA7) -> -6 | CC8: =SUM(CC5:CC7) -> -53 | CH8: =SUM(CH5:CH7) -> -53 | CJ8: =SUM(CJ5:CJ7) -> -33 | CO8: =SUM(CO5:CO7) -> -33 | CQ8: =SUM(CQ5:CQ7) -> -34 | CV8: =SUM(CV5:CV7) -> -34 | CX8: =SUM(CX5:CX7) -> 8 | DC8: =SUM(DC5:DC7) -> 8 | DE8: =SUM(DE5:DE7) -> -38 | DJ8: =SUM(DJ5:DJ7) -> -38 | DL8: =SUM(DL5:DL7) -> -9 | DQ8: =SUM(DQ5:DQ7) -> -9 | DS8: =SUM(DS5:DS7) -> 13 | DX8: =SUM(DX5:DX7) -> 13 | DZ8: =SUM(DZ5:DZ7) -> 16 | EE8: =SUM(EE5:EE7) -> 16 | EG8: =SUM(EG5:EG7) -> 17 | EL8: =SUM(EL5:EL7) -> 17 | EN8: =SUM(EN5:EN7) -> 15 | ES8: =SUM(ES5:ES7) -> 15
A10: Diferencia Real vs Ideal (MWh) | I10: =I5-D5 -> 0 | P10: =P5-K5 -> -4.4792746 | W10: =W5-R5 -> 7.7202073 | AD10: =AD5-Y5 -> 6.0958549 | AK10: =AK5-AF5 -> 3.0958549 | AR10: =AR5-AM5 -> 0.088082902 | AY10: =AY5-AT5 -> -0.19170984 | BF10: =BF5-BA5 -> 2.984456 | BM10: =BM5-BH5 -> -25.145078 | BT10: =BT5-BO5 -> -7.8963731 | CA10: =CA5-BV5 -> 6.3678756 | CH10: =CH5-CC5 -> -14.417098 | CO10: =CO5-CJ5 -> -9.9766839 | CV10: =CV5-CQ5 -> -11.248705 | DC10: =DC5-CX5 -> 8.1761658 | DJ10: =DJ5-DE5 -> -8.3367876 | DQ10: =DQ5-DL5 -> 0.55181347 | DX10: =DX5-DS5 -> -1.4637306 | EE10: =EE5-DZ5 -> -1.6476684 | EL10: =EL5-EG5 -> -3.3756477 | ES10: =ES5-EN5 -> -1.9196891
A11: Tiempo entre consignas | I11: =J3-C3 -> 0.0090277778 | P11: =Q3-J3 -> 0.0034722222 | W11: =X3-Q3 -> 0.0034722222 | AD11: =AE3-X3 -> 0.0020833333 | AK11: =AL3-AE3 -> 0.016666667 | AR11: =AS3-AL3 -> 0.0034722222 | AY11: =AZ3-AS3 -> 0.0048611111 | BF11: =BG3-AZ3 -> 0.065972222 | BM11: =BN3-BG3 -> 0.020138889 | BT11: =BU3-BN3 -> 0.059027778 | CA11: =CB3-BU3 -> 0.011111111 | CH11: =CI3-CB3 -> 0.0125 | CO11: =CP3-CI3 -> 0.042361111 | CV11: =CW3-CP3 -> 0.069444444 | DC11: =DD3-CW3 -> 0.069444444 | DJ11: =DK3-DD3 -> 0.00625 | DQ11: =DR3-DK3 -> 0.014583333 | DX11: =DY3-DR3 -> 0.067361111 | EE11: =EF3-DY3 -> 0.0041666667 | EL11: =EM3-EF3 -> 0.0020833333 | ES11: =ET3-ES3 -> 0
A12: P&L MWh | B12: =SUM(C12:FN12) -> -0.026711524 | I12: =(I10*I11)/60 -> 0 | P12: =(P10*P11)/60 -> -0.00025921728 | W12: =(W10*W11)/60 -> 0.00044677125 | AD12: =(AD10*AD11)/60 -> 0.00021166163 | AK12: =(AK10*AK11)/60 -> 0.0008599597 | AR12: =(AR10*AR11)/60 -> 5.0973901e-06 | AY12: =(AY10*AY11)/60 -> -1.5532048e-05 | BF12: =(BF10*BF11)/60 -> 0.0032815199 | BM12: =(BM10*BM11)/60 -> -0.0084398988 | BT12: =(BT10*BT11)/60 -> -0.0077684226 | CA12: =(CA10*CA11)/60 -> 0.0011792362 | CH12: =(CH10*CH11)/60 -> -0.0030035622 | CO12: =(CO10*CO11)/60 -> -0.0070437236 | CV12: =(CV10*CV11)/60 -> -0.013019334 | DC12: =(DC10*DC11)/60 -> 0.0094631549 | DJ12: =(DJ10*DJ11)/60 -> -0.00086841537 | DQ12: =(DQ10*DQ11)/60 -> 0.00013412133 | DX12: =(DX10*DX11)/60 -> -0.0016433086 | EE12: =(EE10*EE11)/60 -> -0.00011442142 | EL12: =(EL10*EL11)/60 -> -0.00011720999 | ES12: =(ES10*ES11)/60 -> 0
A13: US$ / MWh | B13: 80
A14: P&L US$ | B14: =B12*B13 -> -2.1369219
A15: MWac max de Generación | B15: SITE | C15: % DEL TOTAL
A16: 105 | B16: PFV-ELPELICANO | C16: =A16/$A$19 -> 0.27202073
A17: 196 | B17: PFV-ELROMERO | C17: =A17/$A$19 -> 0.50777202
A18: 85 | B18: PFV-LAHUELLA | C18: =A18/$A$19 -> 0.22020725
A19: =SUM(A16:A18) -> 386
C114: 07:26 | D114: 07:39 | E114: 07:44 | F114: 07:49 | G114: 07:52 | H114: 08:16 | I114: 08:21 | J114: 08:28 | K114: 10:03 | L114: 10:32 | M114: 11:57 | N114: 12:13 | O114: 12:31 | P114: 13:32 | Q114: 15:12 | R114: 16:52 | S114: 17:01 | T114: 17:22 | U114: 18:59 | V114: 19:05 | W114: 19:08
C115: =E5 -> 13.5 | D115: =L5 -> 28.5 | E115: =S5 -> 24.4 | F115: =Z5 -> 20.7 | G115: =AG5 -> 15.3 | H115: =AN5 -> 16.2 | I115: =AU5 -> 19.2 | J115: =BB5 -> 23.9 | K115: =BI5 -> 35.3 | L115: =BP5 -> 38.3 | M115: =BW5 -> 30 | N115: =CD5 -> 29.9 | O115: =CK5 -> 30.7 | P115: =CR5 -> 33.2 | Q115: =CY5 -> 26.6 | R115: =DF5 -> 24.6 | S115: =DM5 -> 22.2 | T115: =DT5 -> 27.3 | U115: =EA5 -> 32.6 | V115: =EH5 -> 34.9 | W115: =EO5 -> 33
C116: =E6 -> 5.6 | D116: =L6 -> 21 | E116: =S6 -> 25.2 | F116: =Z6 -> 27.8 | G116: =AG6 -> 27.7 | H116: =AN6 -> 29.3 | I116: =AU6 -> 34.9 | J116: =BB6 -> 43.3 | K116: =BI6 -> 64 | L116: =BP6 -> 69.3 | M116: =BW6 -> 76.4 | N116: =CD6 -> 76.4 | O116: =CK6 -> 76.4 | P116: =CR6 -> 76.4 | Q116: =CY6 -> 78.6 | R116: =DF6 -> 44.7 | S116: =DM6 -> 40.3 | T116: =DT6 -> 49.4 | U116: =EA6 -> 22.3 | V116: =EH6 -> 18 | W116: =EO6 -> 16.3
C117: =E7 -> 9.9 | D117: =L7 -> 22.9 | E117: =S7 -> 19.2 | F117: =Z7 -> 16.3 | G117: =AG7 -> 12 | H117: =AN7 -> 12.7 | I117: =AU7 -> 15.1 | J117: =BB7 -> 18.8 | K117: =BI7 -> 27.7 | L117: =BP7 -> 30.1 | M117: =BW7 -> 23.6 | N117: =CD7 -> 23.5 | O117: =CK7 -> 24.2 | P117: =CR7 -> 26.1 | Q117: =CY7 -> 20.9 | R117: =DF7 -> 19.4 | S117: =DM7 -> 17.5 | T117: =DT7 -> 21.4 | U117: =EA7 -> 25.6 | V117: =EH7 -> 29.3 | W117: =EO7 -> 27.4

Sheet 2025_11_02
A3: FECHA | B3: GENERADORA | C3: 0.30555556 | J3: 0.32083333 | Q3: 0.32361111 | X3: 0.34375 | AE3: 0.35902778 | AL3: 0.3875 | AS3: 0.40555556 | AZ3: 0.44861111 | BG3: 0.46388889 | BN3: 0.49097222 | BU3: 0.51805556 | CB3: 0.52222222 | CI3: 0.55555556 | CP3: 0.67013889 | CW3: 0.69652778 | DD3: 0.70347222 | DK3: 0.73333333 | DR3: 0.75763889 | DY3: 0.76180556 | EF3: 0.79513889 | EM3: 0.79791667
C4: POTENCIA ACTIVA (MW) | D4: AUMENTO / DISMINUCION REAL (MW) | E4: NUEVO SET POINT POTENCIA ACTIVA (MW) | F4: % DEL AUMENTO / DISMINUCION DEL TOTAL | G4: % DE AUMENTO / DISMINUCION IDEAL | H4: % DIFERENCIA | I4: AUMENTO / DISMINUCION IDEAL (MW) | J4: POTENCIA ACTIVA (MW) | K4: AUMENTO / DISMINUCION REAL (MW) | L4: NUEVO SET POINT POTENCIA ACTIVA (MW) | M4: % DEL AUMENTO / DISMINUCION DEL TOTAL | N4: % DE AUMENTO / DISMINUCION IDEAL | O4: % DIFERENCIA | P4: AUMENTO / DISMINUCION IDEAL (MW) | Q4: POTENCIA ACTIVA (MW) | R4: AUMENTO / DISMINUCION REAL (MW) | S4: NUEVO SET POINT POTENCIA ACTIVA (MW) | T4: % DEL AUMENTO / DISMINUCION DEL TOTAL | U4: % DE AUMENTO / DISMINUCION IDEAL | V4: % DIFERENCIA | W4: AUMENTO / DISMINUCION IDEAL (MW) | X4: POTENCIA ACTIVA (MW) | Y4: AUMENTO / DISMINUCION REAL (MW) | Z4: NUEVO SET POINT POTENCIA ACTIVA (MW) | AA4: % DEL AUMENTO / DISMINUCION DEL TOTAL | AB4: % DE AUMENTO / DISMINUCION IDEAL | AC4: % DIFERENCIA | AD4: AUMENTO / DISMINUCION IDEAL (MW) | AE4: POTENCIA ACTIVA (MW) | AF4: AUMENTO / DISMINUCION REAL (MW) | AG4: NUEVO SET POINT POTENCIA ACTIVA (MW) | AH4: % DEL AUMENTO / DISMINUCION DEL TOTAL | AI4: % DE AUMENTO / DISMINUCION IDEAL | AJ4: % DIFERENCIA | AK4: AUMENTO / DISMINUCION IDEAL (MW) | AL4: POTENCIA ACTIVA (MW) | AM4: AUMENTO / DISMINUCION REAL (MW) | AN4: NUEVO SET POINT POTENCIA ACTIVA (MW) | AO4: % DEL AUMENTO / DISMINUCION DEL TOTAL | AP4: % DE AUMENTO / DISMINUCION IDEAL | AQ4: % DIFERENCIA | AR4: AUMENTO / DISMINUCION IDEAL (MW) | AS4: POTENCIA ACTIVA (MW) | AT4: AUMENTO / DISMINUCION REAL (MW) | AU4: NUEVO SET POINT POTENCIA ACTIVA (MW) | AV4: % DEL AUMENTO / DISMINUCION DEL TOTAL | AW4: % DE AUMENTO / DISMINUCION IDEAL | AX4: % DIFERENCIA | AY4: AUMENTO / DISMINUCION IDEAL (MW) | AZ4: POTENCIA ACTIVA (MW) | BA4: AUMENTO / DISMINUCION REAL (MW) | BB4: NUEVO SET POINT POTENCIA ACTIVA (MW) | BC4: % DEL AUMENTO / DISMINUCION DEL TOTAL | BD4: % DE AUMENTO / DISMINUCION IDEAL | BE4: % DIFERENCIA | BF4: AUMENTO / DISMINUCION IDEAL (MW) | BG4: POTENCIA ACTIVA (MW) | BH4: AUMENTO / DISMINUCION REAL (MW) | BI4: NUEVO SET POINT POTENCIA ACTIVA (MW) | BJ4: % DEL AUMENTO / DISMINUCION DEL TOTAL | BK4: % DE AUMENTO / DISMINUCION IDEAL | BL4: % DIFERENCIA | BM4: AUMENTO / DISMINUCION IDEAL (MW) | BN4: POTENCIA ACTIVA (MW) | BO4: AUMENTO / DISMINUCION REAL (MW) | BP4: NUEVO SET POINT POTENCIA ACTIVA (MW) | BQ4: % DEL AUMENTO / DISMINUCION DEL TOTAL | BR4: % DE AUMENTO / DISMINUCION IDEAL | BS4: % DIFERENCIA | BT4: AUMENTO / DISMINUCION IDEAL (MW) | BU4: POTENCIA ACTIVA (MW) | BV4: AUMENTO / DISMINUCION REAL (MW) | BW4: NUEVO SET POINT POTENCIA ACTIVA (MW) | BX4: % DEL AUMENTO / DISMINUCION DEL TOTAL | BY4: % DE AUMENTO / DISMINUCION IDEAL | BZ4: % DIFERENCIA | CA4: AUMENTO / DISMINUCION IDEAL (MW) | CB4: POTENCIA ACTIVA (MW) | CC4: AUMENTO / DISMINUCION REAL (MW) | CD4: NUEVO SET POINT POTENCIA ACTIVA (MW) | CE4: % DEL AUMENTO / DISMINUCION DEL TOTAL | CF4: % DE AUMENTO / DISMINUCION IDEAL | CG4: % DIFERENCIA | CH4: AUMENTO / DISMINUCION IDEAL (MW) | CI4: POTENCIA ACTIVA (MW) | CJ4: AUMENTO / DISMINUCION REAL (MW) | CK4: NUEVO SET POINT POTENCIA ACTIVA (MW) | CL4: % DEL AUMENTO / DISMINUCION DEL TOTAL | CM4: % DE AUMENTO / DISMINUCION IDEAL | CN4: % DIFERENCIA | CO4: AUMENTO / DISMINUCION IDEAL (MW) | CP4: POTENCIA ACTIVA (MW) | CQ4: AUMENTO / DISMINUCION REAL (MW) | CR4: NUEVO SET POINT POTENCIA ACTIVA (MW) | CS4: % DEL AUMENTO / DISMINUCION DEL TOTAL | CT4: % DE AUMENTO / DISMINUCION IDEAL | CU4: % DIFERENCIA | CV4: AUMENTO / DISMINUCION IDEAL (MW) | CW4: POTENCIA ACTIVA (MW) | CX4: AUMENTO / DISMINUCION REAL (MW) | CY4: NUEVO SET POINT POTENCIA ACTIVA (MW) | CZ4: % DEL AUMENTO / DISMINUCION DEL TOTAL | DA4: % DE AUMENTO / DISMINUCION IDEAL | DB4: % DIFERENCIA | DC4: AUMENTO / DISMINUCION IDEAL (MW) | DD4: POTENCIA ACTIVA (MW) | DE4: AUMENTO / DISMINUCION REAL (MW) | DF4: NUEVO SET POINT POTENCIA ACTIVA (MW) | DG4: % DEL AUMENTO / DISMINUCION DEL TOTAL | DH4: % DE AUMENTO / DISMINUCION IDEAL | DI4: % DIFERENCIA | DJ4: AUMENTO / DISMINUCION IDEAL (MW) | DK4: POTENCIA ACTIVA (MW) | DL4: AUMENTO / DISMINUCION REAL (MW) | DM4: NUEVO SET POINT POTENCIA ACTIVA (MW) | DN4: % DEL AUMENTO / DISMINUCION DEL TOTAL | DO4: % DE AUMENTO / DISMINUCION IDEAL | DP4: % DIFERENCIA | DQ4: AUMENTO / DISMINUCION IDEAL (MW) | DR4: POTENCIA ACTIVA (MW) | DS4: AUMENTO / DISMINUCION REAL (MW) | DT4: NUEVO SET POINT POTENCIA ACTIVA (MW) | DU4: % DEL AUMENTO / DISMINUCION DEL TOTAL | DV4: % DE AUMENTO / DISMINUCION IDEAL | DW4: % DIFERENCIA | DX4: AUMENTO / DISMINUCION IDEAL (MW) | DY4: POTENCIA ACTIVA (MW) | DZ4: AUMENTO / DISMINUCION REAL (MW) | EA4: NUEVO SET POINT POTENCIA ACTIVA (MW) | EB4: % DEL AUMENTO / DISMINUCION DEL TOTAL | EC4: % DE AUMENTO / DISMINUCION IDEAL | ED4: % DIFERENCIA | EE4: AUMENTO / DISMINUCION IDEAL (MW) | EF4: POTENCIA ACTIVA (MW) | EG4: AUMENTO / DISMINUCION REAL (MW) | EH4: NUEVO SET POINT POTENCIA ACTIVA (MW) | EI4: % DEL AUMENTO / DISMINUCION DEL TOTAL | EJ4: % DE AUMENTO / DISMINUCION IDEAL | EK4: % DIFERENCIA | EL4: AUMENTO / DISMINUCION IDEAL (MW) | EM4: POTENCIA ACTIVA (MW) | EN4: AUMENTO / DISMINUCION REAL (MW) | EO4: NUEVO SET POINT POTENCIA ACTIVA (MW) | EP4: % DEL AUMENTO / DISMINUCION DEL TOTAL | EQ4: % DE AUMENTO / DISMINUCION IDEAL | ER4: % DIFERENCIA | ES4: AUMENTO / DISMINUCION IDEAL (MW)
A5: 45963 | B5: PFV-ELPELICANO | C5: 10 | D5: 0 | E5: 9.9 | F5: =IF($D$8=0,0,D5/$D$8) -> 0 | G5: =C12 -> 0 | H5: =F5-G5 -> 0 | I5: =G5*$D$8 -> 0 | J5: 10 | K5: 12 | L5: 22 | M5: =IF($K$8=0,0,J5/$K$8) -> 0.24390244 | N5: =C16 -> 0.27202073 | O5: =M5-N5 -> -0.028118286 | P5: =N5*$K$8 -> 11.15285 | Q5: 22 | R5: -8 | S5: 14.5 | T5: =R5/$R$8 -> -0.44444444 | U5: =C16 -> 0.27202073 | V5: =T5-U5 -> -0.71646517 | W5: =U5*$R$8 -> 4.8963731 | X5: 15 | Y5: 3 | Z5: 17.7 | AA5: =Y5/Y8 -> 0.088235294 | AB5: =C16 -> 0.27202073 | AC5: =AA5-AB5 -> -0.18378543 | AD5: =AB5*Y8 -> 9.2487047 | AE5: 18 | AF5: 2 | AG5: 20.5 | AH5: =AF5/$AF$8 -> 0.054054054 | AI5: =C16 -> 0.27202073 | AJ5: =AH5-AI5 -> -0.21796667 | AK5: =AI5*$AF$8 -> 10.064767 | AL5: 21 | AM5: 3 | AN5: 24.5 | AO5: =AM5/$AM$8 -> 0.21428571 | AP5: =C16 -> 0.27202073 | AQ5: =AO5-AP5 -> -0.057735011 | AR5: =AP5*$AM$8 -> 3.8082902 | AS5: 25 | AT5: 3 | AU5: 28.4 | AV5: =AT5/$AT$8 -> 0.2 | AW5: =C16 -> 0.27202073 | AX5: =AV5-AW5 -> -0.072020725 | AY5: =AW5*$AT$8 -> 4.0803109 | AZ5: 28 | BA5: 3 | BB5: 31.3 | BC5: =BA5/$BA$8 -> 0.15 | BD5: =C16 -> 0.27202073 | BE5: =BC5-BD5 -> -0.12202073 | BF5: =BD5*$BA$8 -> 5.4404145 | BG5: 31 | BH5: 10 | BI5: 41.4 | BJ5: =BH5/$BH$8 -> -0.83333333 | BK5: =C16 -> 0.27202073 | BL5: =BJ5-BK5 -> -1.1053541 | BM5: =BK5*$BH$8 -> -3.2642487 | BN5: 41 | BO5: -4 | BP5: 36.7 | BQ5: =BO5/$BO$8 -> -0.12121212 | BR5: =C16 -> 0.27202073 | BS5: =BQ5-BR5 -> -0.39323285 | BT5: =BR5*$BO$8 -> 8.9766839 | BU5: 37 | BV5: 3 | BW5: 40 | BX5: =BV5/$BV$8 -> -0.15 | BY5: =C16 -> 0.27202073 | BZ5: =BX5-BY5 -> -0.42202073 | CA5: =BY5*$BV$8 -> -5.4404145 | CB5: 40 | CC5: 0 | CD5: 39.9 | CE5: =CC5/$CC$8 -> 0 | CF5: =C16 -> 0.27202073 | CG5: =CE5-CF5 -> -0.27202073 | CH5: =CF5*$CC$8 -> -9.7927461 | CI5: 40 | CJ5: 3 | CK5: 43.4 | CL5: =CJ5/$CJ$8 -> -0.125 | CM5: =C16 -> 0.27202073 | CN5: =CL5-CM5 -> -0.39702073 | CO5: =CM5*$CJ$8 -> -6.5284974 | CP5: 43 | CQ5: -1 | CR5: 42.2 | CS5: =CQ5/$CQ$8 -> 0.025641026 | CT5: =C16 -> 0.27202073 | CU5: =CS5-CT5 -> -0.2463797 | CV5: =CT5*$CQ$8 -> -10.608808 | CW5: 42 | CX5: -6 | CY5: 35.7 | CZ5: =CX5/$CX$8 -> 0.46153846 | DA5: =C16 -> 0.27202073 | DB5: =CZ5-DA5 -> 0.18951774 | DC5: =DA5*$CX$8 -> -3.5362694 | DD5: 36 | DE5: -4 | DF5: 32.3 | DG5: =DE5/$DE$8 -> 0.18181818 | DH5: =C16 -> 0.27202073 | DI5: =DG5-DH5 -> -0.090202544 | DJ5: =DH5*$DE$8 -> -5.984456 | DK5: 36 | DL5: -7 | DM5: 29.3 | DN5: =DL5/$DL$8 -> 0.41176471 | DO5: =C16 -> 0.27202073 | DP5: =DN5-DO5 -> 0.13974398 | DQ5: =DO5*$DL$8 -> -4.6243523 | DR5: 29 | DS5: -4 | DT5: 25.2 | DU5: =DS5/$DS$8 -> 0.30769231 | DV5: =C16 -> 0.27202073 | DW5: =DU5-DV5 -> 0.035671582 | DX5: =DV5*$DS$8 -> -3.5362694 | DY5: 25 | DZ5: 4 | EA5: 28.7 | EB5: =DZ5/$DZ$8 -> 0.30769231 | EC5: =C16 -> 0.27202073 | ED5: =EB5-EC5 -> 0.035671582 | EE5: =EC5*$DZ$8 -> 3.5362694 | EF5: 29 | EG5: 7 | EH5: 36.2 | EI5: =EG5/$EG$8 -> 0.25925926 | EJ5: =C16 -> 0.27202073 | EK5: =EI5-EJ5 -> -0.012761466 | EL5: =EJ5*$EG$8 -> 7.3445596 | EM5: 34 | EN5: 1 | EO5: 35.1 | EP5: =EN5/$EN$8 -> 0.083333333 | EQ5: =C16 -> 0.27202073 | ER5: =EP5-EQ5 -> -0.18868739 | ES5: =EQ5*$EN$8 -> 3.2642487
A6: 45963 | B6: PFV-ELROMERO | C6: 2 | D6: 0 | E6: 4.5 | F6: =IF($D$8=0,0,D6/$D$8) -> 0 | G6: =C13 -> 0 | H6: =F6-G6 -> 0 | I6: =G6*$D$8 -> 0 | J6: 4 | K6: 19 | L6: 22.9 | M6: =IF($K$8=0,0,J6/$K$8) -> 0.097560976 | N6: =C17 -> 0.50777202 | O6: =M6-N6 -> -0.41021105 | P6: =N6*$D$8 -> 0 | Q6: 4 | R6: 22 | S6: 25.8 | T6: =R6/$R$8 -> 1.2222222 | U6: =C17 -> 0.50777202 | V6: =T6-U6 -> 0.7144502 | W6: =U6*$R$8 -> 9.1398964 | X6: 4 | Y6: 28 | Z6: 32 | AA6: =Y6/$Y$8 -> 0.82352941 | AB6: =C17 -> 0.50777202 | AC6: =AA6-AB6 -> 0.31575739 | AD6: =AB6*$Y$8 -> 17.264249 | AE6: 8 | AF6: 30 | AG6: 37.2 | AH6: =AF6/$AF$8 -> 0.81081081 | AI6: =C17 -> 0.50777202 | AJ6: =AH6-AI6 -> 0.30303879 | AK6: =AI6*$AF$8 -> 18.787565 | AL6: 36 | AM6: 8 | AN6: 44.3 | AO6: =AM6/$AM$8 -> 0.57142857 | AP6: =C17 -> 0.50777202 | AQ6: =AO6-AP6 -> 0.063656551 | AR6: =AP6*$AM$8 -> 7.1088083 | AS6: 43 | AT6: 9 | AU6: 51.5 | AV6: =AT6/$AT$8 -> 0.6 | AW6: =C17 -> 0.50777202 | AX6: =AV6-AW6 -> 0.092227979 | AY6: =AW6*$AT$8 -> 7.6165803 | AZ6: 43 | BA6: 14 | BB6: 56.8 | BC6: =BA6/$BA$8 -> 0.7 | BD6: =C17 -> 0.50777202 | BE6: =BC6-BD6 -> 0.19222798 | BF6: =BD6*$BA$8 -> 10.15544 | BG6: 105 | BH6: -30 | BI6: 75.1 | BJ6: =BH6/$BH$8 -> 2.5 | BK6: =C17 -> 0.50777202 | BL6: =BJ6-BK6 -> 1.992228 | BM6: =BK6*$BH$8 -> -6.0932642 | BN6: 26 | BO6: 41 | BP6: 66.6 | BQ6: =BO6/$BO$8 -> 1.2424242 | BR6: =C17 -> 0.50777202 | BS6: =BQ6-BR6 -> 0.73465222 | BT6: =BR6*$BO$8 -> 16.756477 | BU6: 97 | BV6: -25 | BW6: 72.5 | BX6: =BV6/$BV$8 -> 1.25 | BY6: =C17 -> 0.50777202 | BZ6: =BX6-BY6 -> 0.74222798 | CA6: =BY6*$BV$8 -> -10.15544 | CB6: 107 | CC6: -35 | CD6: 72.4 | CE6: =CC6/$CC$8 -> 0.97222222 | CF6: =C17 -> 0.50777202 | CG6: =CE6-CF6 -> 0.4644502 | CH6: =CF6*$CC$8 -> -18.279793 | CI6: 108 | CJ6: -29 | CK6: 78.6 | CL6: =CJ6/$CJ$8 -> 1.2083333 | CM6: =C17 -> 0.50777202 | CN6: =CL6-CM6 -> 0.70056131 | CO6: =CM6*$CJ$8 -> -12.186528 | CP6: 114 | CQ6: -37 | CR6: 76.4 | CS6: =CQ6/$CQ$8 -> 0.94871795 | CT6: =C17 -> 0.50777202 | CU6: =CS6-CT6 -> 0.44094593 | CV6: =CT6*$CQ$8 -> -19.803109 | CW6: 78 | CX6: -2 | CY6: 76.4 | CZ6: =CX6/$CX$8 -> 0.15384615 | DA6: =C17 -> 0.50777202 | DB6: =CZ6-DA6 -> -0.35392587 | DC6: =DA6*$CX$8 -> -6.6010363 | DD6: 75 | DE6: -15 | DF6: 59.4 | DG6: =DE6/$DE$8 -> 0.68181818 | DH6: =C17 -> 0.50777202 | DI6: =DG6-DH6 -> 0.17404616 | DJ6: =DH6*$DE$8 -> -11.170984 | DK6: 58 | DL6: -5 | DM6: 53.1 | DN6: =DL6/$DL$8 -> 0.29411765 | DO6: =C17 -> 0.50777202 | DP6: =DN6-DO6 -> -0.21365437 | DQ6: =DO6*$DL$8 -> -8.6321244 | DR6: 52 | DS6: -6 | DT6: 45.6 | DU6: =DS6/$DS$8 -> 0.46153846 | DV6: =C17 -> 0.50777202 | DW6: =DU6-DV6 -> -0.046233559 | DX6: =DV6*$DS$8 -> -6.6010363 | DY6: 45 | DZ6: 7 | EA6: 52 | EB6: =DZ6/$DZ$8 -> 0.53846154 | EC6: =C17 -> 0.50777202 | ED6: =EB6-EC6 -> 0.030689518 | EE6: =EC6*$DZ$8 -> 6.6010363 | EF6: 45 | EG6: 12 | EH6: 57.2 | EI6: =EG6/$EG$8 -> 0.44444444 | EJ6: =C17 -> 0.50777202 | EK6: =EI6-EJ6 -> -0.063327576 | EL6: =EJ6*$EG$8 -> 13.709845 | EM6: 11 | EN6: 7 | EO6: 18.3 | EP6: =EN6/$EN$8 -> 0.58333333 | EQ6: =C17 -> 0.50777202 | ER6: =EP6-EQ6 -> 0.075561313 | ES6: =EQ6*$EN$8 -> 6.0932642
A7: 45963 | B7: PFV-LAHUELLA | C7: 7 | D7: 0 | E7: 7.2 | F7: =IF($D$8=0,0,D7/$D$8) -> 0 | G7: =C14 -> 0 | H7: =F7-G7 -> 0 | I7: =G7*$D$8 -> 0 | J7: 7 | K7: 10 | L7: 17.4 | M7: =IF($K$8=0,0,J7/$K$8) -> 0.17073171 | N7: =C18 -> 0.22020725 | O7: =M7-N7 -> -0.049475547 | P7: =N7*$D$8 -> 0 | Q7: 7 | R7: 4 | S7: 11.4 | T7: =R7/$R$8 -> 0.22222222 | U7: =C18 -> 0.22020725 | V7: =T7-U7 -> 0.0020149683 | W7: =U7*$R$8 -> 3.9637306 | X7: 11 | Y7: 3 | Z7: 13.9 | AA7: =Y7/$Y$8 -> 0.088235294 | AB7: =C18 -> 0.22020725 | AC7: =AA7-AB7 -> -0.13197196 | AD7: =AB7*$Y$8 -> 7.4870466 | AE7: 11 | AF7: 5 | AG7: 16.1 | AH7: =AF7/$AF$8 -> 0.13513514 | AI7: =C18 -> 0.22020725 | AJ7: =AH7-AI7 -> -0.085072119 | AK7: =AI7*$AF$8 -> 8.1476684 | AL7: 16 | AM7: 3 | AN7: 19.2 | AO7: =AM7/$AM$8 -> 0.21428571 | AP7: =C18 -> 0.22020725 | AQ7: =AO7-AP7 -> -0.0059215396 | AR7: =AP7*$AM$8 -> 3.0829016 | AS7: 19 | AT7: 3 | AU7: 22.3 | AV7: =AT7/$AT$8 -> 0.2 | AW7: =C18 -> 0.22020725 | AX7: =AV7-AW7 -> -0.020207254 | AY7: =AW7*$AT$8 -> 3.3031088 | AZ7: 22 | BA7: 3 | BB7: 24.6 | BC7: =BA7/$BA$8 -> 0.15 | BD7: =C18 -> 0.22020725 | BE7: =BC7-BD7 -> -0.070207254 | BF7: =BD7*$BA$8 -> 4.4041451 | BG7: 25 | BH7: 8 | BI7: 32.6 | BJ7: =BH7/$BH$8 -> -0.66666667 | BK7: =C18 -> 0.22020725 | BL7: =BJ7-BK7 -> -0.88687392 | BM7: =BK7*$BH$8 -> -2.642487 | BN7: 33 | BO7: -4 | BP7: 28.9 | BQ7: =BO7/$BO$8 -> -0.12121212 | BR7: =C18 -> 0.22020725 | BS7: =BQ7-BR7 -> -0.34141938 | BT7: =BR7*$BO$8 -> 7.2668394 | BU7: 29 | BV7: 2 | BW7: 31.5 | BX7: =BV7/$BV$8 -> -0.1 | BY7: =C18 -> 0.22020725 | BZ7: =BX7-BY7 -> -0.32020725 | CA7: =BY7*$BV$8 -> -4.4041451 | CB7: 32 | CC7: -1 | CD7: 31.4 | CE7: =CC7/$CC$8 -> 0.027777778 | CF7: =C18 -> 0.22020725 | CG7: =CE7-CF7 -> -0.19242948 | CH7: =CF7*$CC$8 -> -7.9274611 | CI7: 32 | CJ7: 2 | CK7: 34.1 | CL7: =CJ7/$CJ$8 -> -0.083333333 | CM7: =C18 -> 0.22020725 | CN7: =CL7-CM7 -> -0.30354059 | CO7: =CM7*$CJ$8 -> -5.2849741 | CP7: 34 | CQ7: -1 | CR7: 33.2 | CS7: =CQ7/$CQ$8 -> 0.025641026 | CT7: =C18 -> 0.22020725 | CU7: =CS7-CT7 -> -0.19456623 | CV7: =CT7*$CQ$8 -> -8.5880829 | CW7: 33 | CX7: -5 | CY7: 28.1 | CZ7: =CX7/$CX$8 -> 0.38461538 | DA7: =C18 -> 0.22020725 | DB7: =CZ7-DA7 -> 0.16440813 | DC7: =DA7*$CX$8 -> -2.8626943 | DD7: 28 | DE7: -3 | DF7: 25.4 | DG7: =DE7/$DE$8 -> 0.13636364 | DH7: =C18 -> 0.22020725 | DI7: =DG7-DH7 -> -0.083843618 | DJ7: =DH7*$DE$8 -> -4.8445596 | DK7: 28 | DL7: -5 | DM7: 23 | DN7: =DL7/$DL$8 -> 0.29411765 | DO7: =C18 -> 0.22020725 | DP7: =DN7-DO7 -> 0.073910393 | DQ7: =DO7*$DL$8 -> -3.7435233 | DR7: 23 | DS7: -3 | DT7: 19.8 | DU7: =DS7/$DS$8 -> 0.23076923 | DV7: =C18 -> 0.22020725 | DW7: =DU7-DV7 -> 0.010561977 | DX7: =DV7*$DS$8 -> -2.8626943 | DY7: 20 | DZ7: 2 | EA7: 22.5 | EB7: =DZ7/$DZ$8 -> 0.15384615 | EC7: =C18 -> 0.22020725 | ED7: =EB7-EC7 -> -0.0663611 | EE7: =EC7*$DZ$8 -> 2.8626943 | EF7: 20 | EG7: 8 | EH7: 28.5 | EI7: =EG7/$EG$8 -> 0.2962963 | EJ7: =C18 -> 0.22020725 | EK7: =EI7-EJ7 -> 0.076089042 | EL7: =EJ7*$EG$8 -> 5.9455959 | EM7: 25 | EN7: 4 | EO7: 29.2 | EP7: =EN7/$EN$8 -> 0.33333333 | EQ7: =C18 -> 0.22020725 | ER7: =EP7-EQ7 -> 0.11312608 | ES7: =EQ7*$EN$8 -> 2.642487
D8: =SUM(D5:D7) -> 0 | K8: =SUM(K5:K7) -> 41 | R8: =SUM(R5:R7) -> 18 | Y8: =SUM(Y5:Y7) -> 34 | AD8: =SUM(AD5:AD7) -> 34 | AF8: =SUM(AF5:AF7) -> 37 | AK8: =SUM(AK5:AK7) -> 37 | AM8: =SUM(AM5:AM7) -> 14 | AR8: =SUM(AR5:AR7) -> 14 | AT8: =SUM(AT5:AT7) -> 15 | AY8: =SUM(AY5:AY7) -> 15 | BA8: =SUM(BA5:BA7) -> 20 | BF8: =SUM(BF5:BF7) -> 20 | BH8: =SUM(BH5:BH7) -> -12 | BM8: =SUM(BM5:BM7) -> -12 | BO8: =SUM(BO5:BO7) -> 33 | BT8: =SUM(BT5:BT7) -> 33 | BV8: =SUM(BV5:BV7) -> -20 | CA8: =SUM(CA5:CA7) -> -20 | CC8: =SUM(CC5:CC7) -> -36 | CH8: =SUM(CH5:CH7) -> -36 | CJ8: =SUM(CJ5:CJ7) -> -24 | CO8: =SUM(CO5:CO7) -> -24 | CQ8: =SUM(CQ5:CQ7) -> -39 | CV8: =SUM(CV5:CV7) -> -39 | CX8: =SUM(CX5:CX7) -> -13 | DC8: =SUM(DC5:DC7) -> -13 | DE8: =SUM(DE5:DE7) -> -22 | DJ8: =SUM(DJ5:DJ7) -> -22 | DL8: =SUM(DL5:DL7) -> -17 | DQ8: =SUM(DQ5:DQ7) -> -17 | DS8: =SUM(DS5:DS7) -> -13 | DX8: =SUM(DX5:DX7) -> -13 | DZ8: =SUM(DZ5:DZ7) -> 13 | EE8: =SUM(EE5:EE7) -> 13 | EG8: =SUM(EG5:EG7) -> 27 | EL8: =SUM(EL5:EL7) -> 27 | EN8: =SUM(EN5:EN7) -> 12 | ES8: =SUM(ES5:ES7) -> 12
A10: Diferencia Real vs Ideal (MWh) | I10: =I5-D5 -> 0 | P10: =P5-K5 -> -0.84715026 | W10: =W5-R5 -> 12.896373 | AD10: =AD5-Y5 -> 6.2487047 | AK10: =AK5-AF5 -> 8.0647668 | AR10: =AR5-AM5 -> 0.80829016 | AY10: =AY5-AT5 -> 1.0803109 | BF10: =BF5-BA5 -> 2.4404145 | BM10: =BM5-BH5 -> -13.264249 | BT10: =BT5-BO5 -> 12.976684 | CA10: =CA5-BV5 -> -8.4404145 | CH10: =CH5-CC5 -> -9.7927461 | CO10: =CO5-CJ5 -> -9.5284974 | CV10: =CV5-CQ5 -> -9.6088083 | DC10: =DC5-CX5 -> 2.4637306 | DJ10: =DJ5-DE5 -> -1.984456 | DQ10: =DQ5-DL5 -> 2.3756477 | DX10: =DX5-DS5 -> 0.46373057 | EE10: =EE5-DZ5 -> -0.46373057 | EL10: =EL5-EG5 -> 0.34455959 | ES10: =ES5-EN5 -> 2.2642487
A11: Tiempo entre consignas | I11: =J3-C3 -> 0.015277778 | P11: =Q3-J3 -> 0.0027777778 | W11: =X3-Q3 -> 0.020138889 | AD11: =AE3-X3 -> 0.015277778 | AK11: =AL3-AE3 -> 0.028472222 | AR11: =AS3-AL3 -> 0.018055556 | AY11: =AZ3-AS3 -> 0.043055556 | BF11: =BG3-AZ3 -> 0.015277778 | BM11: =BN3-BG3 -> 0.027083333 | BT11: =BU3-BN3 -> 0.027083333 | CA11: =CB3-BU3 -> 0.0041666667 | CH11: =CI3-CB3 -> 0.033333333 | CO11: =CP3-CI3 -> 0.11458333 | CV11: =CW3-CP3 -> 0.026388889 | DC11: =DD3-CW3 -> 0.0069444444 | DJ11: =DK3-DD3 -> 0.029861111 | DQ11: =DR3-DK3 -> 0.024305556 | DX11: =DY3-DR3 -> 0.0041666667 | EE11: =EF3-DY3 -> 0.033333333 | EL11: =EM3-EF3 -> 0.0027777778 | ES11: =ET3-ES3 -> 0
A12: P&L MWh | B12: =SUM(C12:EW12) -> -0.017181413 | I12: =(I10*I11)/60 -> 0 | P12: =(P10*P11)/60 -> -3.9219919e-05 | W12: =(W10*W11)/60 -> 0.0043286437 | AD12: =(AD10*AD11)/60 -> 0.0015911054 | AK12: =(AK10*AK11)/60 -> 0.0038270306 | AR12: =(AR10*AR11)/60 -> 0.00024323546 | AY12: =(AY10*AY11)/60 -> 0.00077522309 | BF12: =(BF10*BF11)/60 -> 0.00062140184 | BM12: =(BM10*BM11)/60 -> -0.0059873345 | BT12: =(BT10*BT11)/60 -> 0.0058575309 | CA12: =(CA10*CA11)/60 -> -0.0005861399 | CH12: =(CH10*CH11)/60 -> -0.0054404145 | CO12: =(CO10*CO11)/60 -> -0.018196783 | CV12: =(CV10*CV11)/60 -> -0.0042260962 | DC12: =(DC10*DC11)/60 -> 0.000285154 | DJ12: =(DJ10*DJ11)/60 -> -0.00098763433 | DQ12: =(DQ10*DQ11)/60 -> 0.00096235727 | DX12: =(DX10*DX11)/60 -> 3.2203512e-05 | EE12: =(EE10*EE11)/60 -> -0.00025762809 | EL12: =(EL10*EL11)/60 -> 1.5951833e-05 | ES12: =(ES10*ES11)/60 -> 0
A13: US$ / MWh | B13: 80
A14: P&L US$ | B14: =B12*B13 -> -1.374513
A15: MWac max de Generación | B15: SITE | C15: % DEL TOTAL
A16: 105 | B16: PFV-ELPELICANO | C16: =A16/$A$19 -> 0.27202073
A17: 196 | B17: PFV-ELROMERO | C17: =A17/$A$19 -> 0.50777202
A18: 85 | B18: PFV-LAHUELLA | C18: =A18/$A$19 -> 0.22020725
A19: =SUM(A16:A18) -> 386
C114: 0.30555556 | D114: 0.32083333 | E114: 0.32361111 | F114: 0.34375 | G114: 0.35902778 | H114: 0.3875 | I114: 0.40555556 | J114: 0.44861111 | K114: 0.46388889 | L114: 0.49097222 | M114: 0.51805556 | N114: 0.52222222 | O114: 0.55555556 | P114: 0.67013889 | Q114: 0.69652778 | R114: 0.70347222 | S114: 0.73333333 | T114: 0.75763889 | U114: 0.76180556 | V114: 0.79513889 | W114: 0.79791667
C115: =E5 -> 9.9 | D115: =L5 -> 22 | E115: =S5 -> 14.5 | F115: =Z5 -> 17.7 | G115: =AG5 -> 20.5 | H115: =AN5 -> 24.5 | I115: =AU5 -> 28.4 | J115: =BB5 -> 31.3 | K115: =BI5 -> 41.4 | L115: =BP5 -> 36.7 | M115: =BW5 -> 40 | N115: =CD5 -> 39.9 | O115: =CK5 -> 43.4 | P115: =CR5 -> 42.2 | Q115: =CY5 -> 35.7 | R115: =DF5 -> 32.3 | S115: =DM5 -> 29.3 | T115: =DT5 -> 25.2 | U115: =EA5 -> 28.7 | V115: =EH5 -> 36.2 | W115: =EO5 -> 35.1
C116: =E6 -> 4.5 | D116: =L6 -> 22.9 | E116: =S6 -> 25.8 | F116: =Z6 -> 32 | G116: =AG6 -> 37.2 | H116: =AN6 -> 44.3 | I116: =AU6 -> 51.5 | J116: =BB6 -> 56.8 | K116: =BI6 -> 75.1 | L116: =BP6 -> 66.6 | M116: =BW6 -> 72.5 | N116: =CD6 -> 72.4 | O116: =CK6 -> 78.6 | P116: =CR6 -> 76.4 | Q116: =CY6 -> 76.4 | R116: =DF6 -> 59.4 | S116: =DM6 -> 53.1 | T116: =DT6 -> 45.6 | U116: =EA6 -> 52 | V116: =EH6 -> 57.2 | W116: =EO6 -> 18.3
C117: =E7 -> 7.2 | D117: =L7 -> 17.4 | E117: =S7 -> 11.4 | F117: =Z7 -> 13.9 | G117: =AG7 -> 16.1 | H117: =AN7 -> 19.2 | I117: =AU7 -> 22.3 | J117: =BB7 -> 24.6 | K117: =BI7 -> 32.6 | L117: =BP7 -> 28.9 | M117: =BW7 -> 31.5 | N117: =CD7 -> 31.4 | O117: =CK7 -> 34.1 | P117: =CR7 -> 33.2 | Q117: =CY7 -> 28.1 | R117: =DF7 -> 25.4 | S117: =DM7 -> 23 | T117: =DT7 -> 19.8 | U117: =EA7 -> 22.5 | V117: =EH7 -> 28.5 | W117: =EO7 -> 29.2

Sheet 2025_11_03
A3: FECHA | B3: GENERADORA | C3: 0.31111111 | J3: 0.31944444 | Q3: 0.32222222 | X3: 0.33263889 | AE3: 0.33541667 | AL3: 0.34652778 | AS3: 0.36527778 | AZ3: 0.38680556 | BG3: 0.39513889 | BN3: 0.49930556 | BU3: 0.50902778 | CB3: 0.525 | CI3: 0.53541667 | CP3: 0.53958333 | CW3: 0.54513889 | DD3: 0.55902778 | DK3: 0.62013889 | DR3: 0.65 | DY3: 0.66319444 | EF3: 0.67638889 | EM3: 0.70069444 | ET3: 0.7125 | FA3: 0.72777778 | FH3: 0.78194444
C4: POTENCIA ACTIVA (MW) | D4: AUMENTO / DISMINUCION REAL (MW) | E4: NUEVO SET POINT POTENCIA ACTIVA (MW) | F4: % DEL AUMENTO / DISMINUCION DEL TOTAL | G4: % DE AUMENTO / DISMINUCION IDEAL | H4: % DIFERENCIA | I4: AUMENTO / DISMINUCION IDEAL (MW) | J4: POTENCIA ACTIVA (MW) | K4: AUMENTO / DISMINUCION REAL (MW) | L4: NUEVO SET POINT POTENCIA ACTIVA (MW) | M4: % DEL AUMENTO / DISMINUCION DEL TOTAL | N4: % DE AUMENTO / DISMINUCION IDEAL | O4: % DIFERENCIA | P4: AUMENTO / DISMINUCION IDEAL (MW) | Q4: POTENCIA ACTIVA (MW) | R4: AUMENTO / DISMINUCION REAL (MW) | S4: NUEVO SET POINT POTENCIA ACTIVA (MW) | T4: % DEL AUMENTO / DISMINUCION DEL TOTAL | U4: % DE AUMENTO / DISMINUCION IDEAL | V4: % DIFERENCIA | W4: AUMENTO / DISMINUCION IDEAL (MW) | X4: POTENCIA ACTIVA (MW) | Y4: AUMENTO / DISMINUCION REAL (MW) | Z4: NUEVO SET POINT POTENCIA ACTIVA (MW) | AA4: % DEL AUMENTO / DISMINUCION DEL TOTAL | AB4: % DE AUMENTO / DISMINUCION IDEAL | AC4: % DIFERENCIA | AD4: AUMENTO / DISMINUCION IDEAL (MW) | AE4: POTENCIA ACTIVA (MW) | AF4: AUMENTO / DISMINUCION REAL (MW) | AG4: NUEVO SET POINT POTENCIA ACTIVA (MW) | AH4: % DEL AUMENTO / DISMINUCION DEL TOTAL | AI4: % DE AUMENTO / DISMINUCION IDEAL | AJ4: % DIFERENCIA | AK4: AUMENTO / DISMINUCION IDEAL (MW) | AL4: POTENCIA ACTIVA (MW) | AM4: AUMENTO / DISMINUCION REAL (MW) | AN4: NUEVO SET POINT POTENCIA ACTIVA (MW) | AO4: % DEL AUMENTO / DISMINUCION DEL TOTAL | AP4: % DE AUMENTO / DISMINUCION IDEAL | AQ4: % DIFERENCIA | AR4: AUMENTO / DISMINUCION IDEAL (MW) | AS4: POTENCIA ACTIVA (MW) | AT4: AUMENTO / DISMINUCION REAL (MW) | AU4: NUEVO SET POINT POTENCIA ACTIVA (MW) | AV4: % DEL AUMENTO / DISMINUCION DEL TOTAL | AW4: % DE AUMENTO / DISMINUCION IDEAL | AX4: % DIFERENCIA | AY4: AUMENTO / DISMINUCION IDEAL (MW) | AZ4: POTENCIA ACTIVA (MW) | BA4: AUMENTO / DISMINUCION REAL (MW) | BB4: NUEVO SET POINT POTENCIA ACTIVA (MW) | BC4: % DEL AUMENTO / DISMINUCION DEL TOTAL | BD4: % DE AUMENTO / DISMINUCION IDEAL | BE4: % DIFERENCIA | BF4: AUMENTO / DISMINUCION IDEAL (MW) | BG4: POTENCIA ACTIVA (MW) | BH4: AUMENTO / DISMINUCION REAL (MW) | BI4: NUEVO SET POINT POTENCIA ACTIVA (MW) | BJ4: % DEL AUMENTO / DISMINUCION DEL TOTAL | BK4: % DE AUMENTO / DISMINUCION IDEAL | BL4: % DIFERENCIA | BM4: AUMENTO / DISMINUCION IDEAL (MW) | BN4: POTENCIA ACTIVA (MW) | BO4: AUMENTO / DISMINUCION REAL (MW) | BP4: NUEVO SET POINT POTENCIA ACTIVA (MW) | BQ4: % DEL AUMENTO / DISMINUCION DEL TOTAL | BR4: % DE AUMENTO / DISMINUCION IDEAL | BS4: % DIFERENCIA | BT4: AUMENTO / DISMINUCION IDEAL (MW) | BU4: POTENCIA ACTIVA (MW) | BV4: AUMENTO / DISMINUCION REAL (MW) | BW4: NUEVO SET POINT POTENCIA ACTIVA (MW) | BX4: % DEL AUMENTO / DISMINUCION DEL TOTAL | BY4: % DE AUMENTO / DISMINUCION IDEAL | BZ4: % DIFERENCIA | CA4: AUMENTO / DISMINUCION IDEAL (MW) | CB4: POTENCIA ACTIVA (MW) | CC4: AUMENTO / DISMINUCION REAL (MW) | CD4: NUEVO SET POINT POTENCIA ACTIVA (MW) | CE4: % DEL AUMENTO / DISMINUCION DEL TOTAL | CF4: % DE AUMENTO / DISMINUCION IDEAL | CG4: % DIFERENCIA | CH4: AUMENTO / DISMINUCION IDEAL (MW) | CI4: POTENCIA ACTIVA (MW) | CJ4: AUMENTO / DISMINUCION REAL (MW) | CK4: NUEVO SET POINT POTENCIA ACTIVA (MW) | CL4: % DEL AUMENTO / DISMINUCION DEL TOTAL | CM4: % DE AUMENTO / DISMINUCION IDEAL | CN4: % DIFERENCIA | CO4: AUMENTO / DISMINUCION IDEAL (MW) | CP4: POTENCIA ACTIVA (MW) | CQ4: AUMENTO / DISMINUCION REAL (MW) | CR4: NUEVO SET POINT POTENCIA ACTIVA (MW) | CS4: % DEL AUMENTO / DISMINUCION DEL TOTAL | CT4: % DE AUMENTO / DISMINUCION IDEAL | CU4: % DIFERENCIA | CV4: AUMENTO / DISMINUCION IDEAL (MW) | CW4: POTENCIA ACTIVA (MW) | CX4: AUMENTO / DISMINUCION REAL (MW) | CY4: NUEVO SET POINT POTENCIA ACTIVA (MW) | CZ4: % DEL AUMENTO / DISMINUCION DEL TOTAL | DA4: % DE AUMENTO / DISMINUCION IDEAL | DB4: % DIFERENCIA | DC4: AUMENTO / DISMINUCION IDEAL (MW) | DD4: POTENCIA ACTIVA (MW) | DE4: AUMENTO / DISMINUCION REAL (MW) | DF4: NUEVO SET POINT POTENCIA ACTIVA (MW) | DG4: % DEL AUMENTO / DISMINUCION DEL TOTAL | DH4: % DE AUMENTO / DISMINUCION IDEAL | DI4: % DIFERENCIA | DJ4: AUMENTO / DISMINUCION IDEAL (MW) | DK4: POTENCIA ACTIVA (MW) | DL4: AUMENTO / DISMINUCION REAL (MW) | DM4: NUEVO SET POINT POTENCIA ACTIVA (MW) | DN4: % DEL AUMENTO / DISMINUCION DEL TOTAL | DO4: % DE AUMENTO / DISMINUCION IDEAL | DP4: % DIFERENCIA | DQ4: AUMENTO / DISMINUCION IDEAL (MW) | DR4: POTENCIA ACTIVA (MW) | DS4: AUMENTO / DISMINUCION REAL (MW) | DT4: NUEVO SET POINT POTENCIA ACTIVA (MW) | DU4: % DEL AUMENTO / DISMINUCION DEL TOTAL | DV4: % DE AUMENTO / DISMINUCION IDEAL | DW4: % DIFERENCIA | DX4: AUMENTO / DISMINUCION IDEAL (MW) | DY4: POTENCIA ACTIVA (MW) | DZ4: AUMENTO / DISMINUCION REAL (MW) | EA4: NUEVO SET POINT POTENCIA ACTIVA (MW) | EB4: % DEL AUMENTO / DISMINUCION DEL TOTAL | EC4: % DE AUMENTO / DISMINUCION IDEAL | ED4: % DIFERENCIA | EE4: AUMENTO / DISMINUCION IDEAL (MW) | EF4: POTENCIA ACTIVA (MW) | EG4: AUMENTO / DISMINUCION REAL (MW) | EH4: NUEVO SET POINT POTENCIA ACTIVA (MW) | EI4: % DEL AUMENTO / DISMINUCION DEL TOTAL | EJ4: % DE AUMENTO / DISMINUCION IDEAL | EK4: % DIFERENCIA | EL4: AUMENTO / DISMINUCION IDEAL (MW) | EM4: POTENCIA ACTIVA (MW) | EN4: AUMENTO / DISMINUCION REAL (MW) | EO4: NUEVO SET POINT POTENCIA ACTIVA (MW) | EP4: % DEL AUMENTO / DISMINUCION DEL TOTAL | EQ4: % DE AUMENTO / DISMINUCION IDEAL | ER4: % DIFERENCIA | ES4: AUMENTO / DISMINUCION IDEAL (MW) | ET4: POTENCIA ACTIVA (MW) | EU4: AUMENTO / DISMINUCION REAL (MW) | EV4: NUEVO SET POINT POTENCIA ACTIVA (MW) | EW4: % DEL AUMENTO / DISMINUCION DEL TOTAL | EX4: % DE AUMENTO / DISMINUCION IDEAL | EY4: % DIFERENCIA | EZ4: AUMENTO / DISMINUCION IDEAL (MW) | FA4: POTENCIA ACTIVA (MW) | FB4: AUMENTO / DISMINUCION REAL (MW) | FC4: NUEVO SET POINT POTENCIA ACTIVA (MW) | FD4: % DEL AUMENTO / DISMINUCION DEL TOTAL | FE4: % DE AUMENTO / DISMINUCION IDEAL | FF4: % DIFERENCIA | FG4: AUMENTO / DISMINUCION IDEAL (MW) | FH4: POTENCIA ACTIVA (MW) | FI4: AUMENTO / DISMINUCION REAL (MW) | FJ4: NUEVO SET POINT POTENCIA ACTIVA (MW) | FK4: % DEL AUMENTO / DISMINUCION DEL TOTAL | FL4: % DE AUMENTO / DISMINUCION IDEAL | FM4: % DIFERENCIA | FN4: AUMENTO / DISMINUCION IDEAL (MW)
A5: 45964 | B5: PFV-ELPELICANO | C5: 13 | D5: 2 | E5: 14.6 | F5: =IF($D$8=0,0,D5/$D$8) -> 0.14285714 | G5: =C16 -> 0.27202073 | H5: =F5-G5 -> -0.12916358 | I5: =G5*$D$8 -> 3.8082902 | J5: 15 | K5: 14 | L5: 28.7 | M5: =IF($K$8=0,0,J5/$K$8) -> 0.42857143 | N5: =C16 -> 0.27202073 | O5: =M5-N5 -> 0.1565507 | P5: =N5*$K$8 -> 9.5207254 | Q5: 17 | R5: 19 | S5: 36.1 | T5: =R5/$R$8 -> 0.57575758 | U5: =C16 -> 0.27202073 | V5: =T5-U5 -> 0.30373685 | W5: =U5*$R$8 -> 8.9766839 | X5: 14 | Y5: 2 | Z5: 15.4 | AA5: =Y5/Y8 -> 0.18181818 | AB5: =C16 -> 0.27202073 | AC5: =AA5-AB5 -> -0.090202544 | AD5: =AB5*Y8 -> 2.992228 | AE5: 36 | AF5: 0 | AG5: 35.9 | AH5: =AF5/$AF$8 -> 0 | AI5: =C16 -> 0.27202073 | AJ5: =AH5-AI5 -> -0.27202073 | AK5: =AI5*$AF$8 -> 6.8005181 | AL5: 36 | AM5: 19 | AN5: 54.9 | AO5: =AM5/$AM$8 -> 0.5 | AP5: =C16 -> 0.27202073 | AQ5: =AO5-AP5 -> 0.22797927 | AR5: =AP5*$AM$8 -> 10.336788 | AS5: 64 | AT5: 10 | AU5: 74.5 | AV5: =AT5/$AT$8 -> 0.20408163 | AW5: =C16 -> 0.27202073 | AX5: =AV5-AW5 -> -0.067939093 | AY5: =AW5*$AT$8 -> 13.329016 | AZ5: 75 | BA5: -8 | BB5: 67.2 | BC5: =BA5/$BA$8 -> -0.53333333 | BD5: =C16 -> 0.27202073 | BE5: =BC5-BD5 -> -0.80535406 | BF5: =BD5*$BA$8 -> 4.0803109 | BG5: 67 | BH5: 5 | BI5: 72.7 | BJ5: =BH5/$BH$8 -> 0.17857143 | BK5: =C16 -> 0.27202073 | BL5: =BJ5-BK5 -> -0.093449297 | BM5: =BK5*$BH$8 -> 7.6165803 | BN5: 73 | BO5: -7 | BP5: 66.3 | BQ5: =BO5/$BO$8 -> 1 | BR5: =C16 -> 0.27202073 | BS5: =BQ5-BR5 -> 0.72797927 | BT5: =BR5*$BO$8 -> -1.9041451 | BU5: 66 | BV5: -3 | BW5: 63.5 | BX5: =BV5/$BV$8 -> -0.057692308 | BY5: =C16 -> 0.27202073 | BZ5: =BX5-BY5 -> -0.32971303 | CA5: =BY5*$BV$8 -> 14.145078 | CB5: 64 | CC5: -5 | CD5: 58.9 | CE5: =CC5/$CC$8 -> -0.14705882 | CF5: =C16 -> 0.27202073 | CG5: =CE5-CF5 -> -0.41907955 | CH5: =CF5*$CC$8 -> 9.2487047 | CI5: 59 | CJ5: -5 | CK5: 54.2 | CL5: =CJ5/$CJ$8 -> -0.11363636 | CM5: =C16 -> 0.27202073 | CN5: =CL5-CM5 -> -0.38565709 | CO5: =CM5*$CJ$8 -> 11.968912 | CP5: 54 | CQ5: -5 | CR5: 49.1 | CS5: =CQ5/$CQ$8 -> -0.11904762 | CT5: =C16 -> 0.27202073 | CU5: =CS5-CT5 -> -0.39106834 | CV5: =CT5*$CQ$8 -> 11.42487 | CW5: 49 | CX5: -4 | CY5: 45.1 | CZ5: =CX5/$CX$8 -> -0.23529412 | DA5: =C16 -> 0.27202073 | DB5: =CZ5-DA5 -> -0.50731484 | DC5: =DA5*$CX$8 -> 4.6243523 | DD5: 45 | DE5: 2 | DF5: 47.5 | DG5: =DE5/$DE$8 -> -0.058823529 | DH5: =C16 -> 0.27202073 | DI5: =DG5-DH5 -> -0.33084425 | DJ5: =DH5*$DE$8 -> -9.2487047 | DK5: 48 | DL5: -2 | DM5: 46.3 | DN5: =DL5/$DL$8 -> -0.4 | DO5: =C16 -> 0.27202073 | DP5: =DN5-DO5 -> -0.67202073 | DQ5: =DO5*$DL$8 -> 1.3601036 | DR5: 46 | DS5: -4 | DT5: 42.4 | DU5: =DS5/$DS$8 -> -0.28571429 | DV5: =C16 -> 0.27202073 | DW5: =DU5-DV5 -> -0.55773501 | DX5: =DV5*$DS$8 -> 3.8082902 | DY5: 42 | DZ5: 6 | EA5: 47.8 | EB5: =DZ5/$DZ$8 -> -0.090909091 | EC5: =C16 -> 0.27202073 | ED5: =EB5-EC5 -> -0.36292982 | EE5: =EC5*$DZ$8 -> -17.953368 | EF5: 48 | EG5: 3 | EH5: 50.9 | EI5: =EG5/$EG$8 -> 0.3 | EJ5: =C16 -> 0.27202073 | EK5: =EI5-EJ5 -> 0.027979275 | EL5: =EJ5*$EG$8 -> 2.7202073 | EM5: 51 | EN5: -8 | EO5: 42.7 | EP5: =EN5/$EN$8 -> 0.28571429 | EQ5: =C16 -> 0.27202073 | ER5: =EP5-EQ5 -> 0.01369356 | ES5: =EQ5*$EN$8 -> -7.6165803 | ET5: 43 | EU5: -6 | EV5: 37.6 | EW5: =EU5/$EU$8 -> 0.31578947 | EX5: =C16 -> 0.27202073 | EY5: =EW5-EX5 -> 0.043768748 | EZ5: =EX5*$EU$8 -> -5.1683938 | FA5: 38 | FB5: 5 | FC5: 42.9 | FD5: =FB5/$FB$8 -> 0.26315789 | FE5: =C16 -> 0.27202073 | FF5: =FD5-FE5 -> -0.0088628307 | FG5: =FE5*$FB$8 -> 5.1683938 | FH5: 52 | FI5: 2 | FJ5: 54 | FK5: =FI5/$FI$8 -> 0.15384615 | FL5: =C16 -> 0.27202073 | FM5: =FK5-FL5 -> -0.11817457 | FN5: =FL5*$FI$8 -> 3.5362694
A6: 45964 | B6: PFV-ELROMERO | C6: 12 | D6: 10 | E6: 21.7 | F6: =IF($D$8=0,0,D6/$D$8) -> 0.71428571 | G6: =C17 -> 0.50777202 | H6: =F6-G6 -> 0.20651369 | I6: =G6*$D$8 -> 7.1088083 | J6: 21 | K6: 11 | L6: 32.1 | M6: =IF($K$8=0,0,J6/$K$8) -> 0.6 | N6: =C17 -> 0.50777202 | O6: =M6-N6 -> 0.092227979 | P6: =N6*$D$8 -> 7.1088083 | Q6: 17 | R6: 11 | S6: 28 | T6: =R6/$R$8 -> 0.33333333 | U6: =C17 -> 0.50777202 | V6: =T6-U6 -> -0.17443869 | W6: =U6*$R$8 -> 16.756477 | X6: 21 | Y6: 7 | Z6: 27.8 | AA6: =Y6/$Y$8 -> 0.63636364 | AB6: =C17 -> 0.50777202 | AC6: =AA6-AB6 -> 0.12859162 | AD6: =AB6*$Y$8 -> 5.5854922 | AE6: 32 | AF6: 9 | AG6: 40.7 | AH6: =AF6/$AF$8 -> 0.36 | AI6: =C17 -> 0.50777202 | AJ6: =AH6-AI6 -> -0.14777202 | AK6: =AI6*$AF$8 -> 12.694301 | AL6: 35 | AM6: 11 | AN6: 45.7 | AO6: =AM6/$AM$8 -> 0.28947368 | AP6: =C17 -> 0.50777202 | AQ6: =AO6-AP6 -> -0.21829834 | AR6: =AP6*$AM$8 -> 19.295337 | AS6: 45 | AT6: 25 | AU6: 70.7 | AV6: =AT6/$AT$8 -> 0.51020408 | AW6: =C17 -> 0.50777202 | AX6: =AV6-AW6 -> 0.0024320609 | AY6: =AW6*$AT$8 -> 24.880829 | AZ6: 70 | BA6: 29 | BB6: 98.4 | BC6: =BA6/$BA$8 -> 1.9333333 | BD6: =C17 -> 0.50777202 | BE6: =BC6-BD6 -> 1.4255613 | BF6: =BD6*$BA$8 -> 7.6165803 | BG6: 97 | BH6: 19 | BI6: 116.1 | BJ6: =BH6/$BH$8 -> 0.67857143 | BK6: =C17 -> 0.50777202 | BL6: =BJ6-BK6 -> 0.17079941 | BM6: =BK6*$BH$8 -> 14.217617 | BN6: 115 | BO6: 5 | BP6: 120.3 | BQ6: =BO6/$BO$8 -> -0.71428571 | BR6: =C17 -> 0.50777202 | BS6: =BQ6-BR6 -> -1.2220577 | BT6: =BR6*$BO$8 -> -3.5544041 | BU6: 58 | BV6: 57 | BW6: 115.1 | BX6: =BV6/$BV$8 -> 1.0961538 | BY6: =C17 -> 0.50777202 | BZ6: =BX6-BY6 -> 0.58838183 | CA6: =BY6*$BV$8 -> 26.404145 | CB6: 64 | CC6: 43 | CD6: 106.7 | CE6: =CC6/$CC$8 -> 1.2647059 | CF6: =C17 -> 0.50777202 | CG6: =CE6-CF6 -> 0.75693386 | CH6: =CF6*$CC$8 -> 17.264249 | CI6: 46 | CJ6: 53 | CK6: 98.3 | CL6: =CJ6/$CJ$8 -> 1.2045455 | CM6: =C17 -> 0.50777202 | CN6: =CL6-CM6 -> 0.69677343 | CO6: =CM6*$CJ$8 -> 22.341969 | CP6: 34 | CQ6: 55 | CR6: 89.1 | CS6: =CQ6/$CQ$8 -> 1.3095238 | CT6: =C17 -> 0.50777202 | CU6: =CS6-CT6 -> 0.80175179 | CV6: =CT6*$CQ$8 -> 21.326425 | CW6: 66 | CX6: 25 | CY6: 90.9 | CZ6: =CX6/$CX$8 -> 1.4705882 | DA6: =C17 -> 0.50777202 | DB6: =CZ6-DA6 -> 0.96281621 | DC6: =DA6*$CX$8 -> 8.6321244 | DD6: 140 | DE6: -38 | DF6: 101.4 | DG6: =DE6/$DE$8 -> 1.1176471 | DH6: =C17 -> 0.50777202 | DI6: =DG6-DH6 -> 0.60987504 | DJ6: =DH6*$DE$8 -> -17.264249 | DK6: 81 | DL6: 8 | DM6: 88.9 | DN6: =DL6/$DL$8 -> 1.6 | DO6: =C17 -> 0.50777202 | DP6: =DN6-DO6 -> 1.092228 | DQ6: =DO6*$DL$8 -> 2.5388601 | DR6: 68 | DS6: 21 | DT6: 88.9 | DU6: =DS6/$DS$8 -> 1.5 | DV6: =C17 -> 0.50777202 | DW6: =DU6-DV6 -> 0.99222798 | DX6: =DV6*$DS$8 -> 7.1088083 | DY6: 163 | DZ6: -76 | EA6: 86.6 | EB6: =DZ6/$DZ$8 -> 1.1515152 | EC6: =C17 -> 0.50777202 | ED6: =EB6-EC6 -> 0.64374313 | EE6: =EC6*$DZ$8 -> -33.512953 | EF6: 87 | EG6: 5 | EH6: 92.3 | EI6: =EG6/$EG$8 -> 0.5 | EJ6: =C17 -> 0.50777202 | EK6: =EI6-EJ6 -> -0.0077720207 | EL6: =EJ6*$EG$8 -> 5.0777202 | EM6: 91 | EN6: -14 | EO6: 77.5 | EP6: =EN6/$EN$8 -> 0.5 | EQ6: =C17 -> 0.50777202 | ER6: =EP6-EQ6 -> -0.0077720207 | ES6: =EQ6*$EN$8 -> -14.217617 | ET6: 77 | EU6: -9 | EV6: 68.2 | EW6: =EU6/$EU$8 -> 0.47368421 | EX6: =C17 -> 0.50777202 | EY6: =EW6-EX6 -> -0.03408781 | EZ6: =EX6*$EU$8 -> -9.6476684 | FA6: 68 | FB6: 10 | FC6: 77.7 | FD6: =FB6/$FB$8 -> 0.52631579 | FE6: =C17 -> 0.50777202 | FF6: =FD6-FE6 -> 0.018543769 | FG6: =FE6*$FB$8 -> 9.6476684 | FH6: 29 | FI6: 6 | FJ6: 34.8 | FK6: =FI6/$FI$8 -> 0.46153846 | FL6: =C17 -> 0.50777202 | FM6: =FK6-FL6 -> -0.046233559 | FN6: =FL6*$FI$8 -> 6.6010363
A7: 45964 | B7: PFV-LAHUELLA | C7: 11 | D7: 2 | E7: 13 | F7: =IF($D$8=0,0,D7/$D$8) -> 0.14285714 | G7: =C18 -> 0.22020725 | H7: =F7-G7 -> -0.077350111 | I7: =G7*$D$8 -> 3.0829016 | J7: 13 | K7: 10 | L7: 22.5 | M7: =IF($K$8=0,0,J7/$K$8) -> 0.37142857 | N7: =C18 -> 0.22020725 | O7: =M7-N7 -> 0.15122132 | P7: =N7*$D$8 -> 3.0829016 | Q7: 14 | R7: 3 | S7: 16.8 | T7: =R7/$R$8 -> 0.090909091 | U7: =C18 -> 0.22020725 | V7: =T7-U7 -> -0.12929816 | W7: =U7*$R$8 -> 7.2668394 | X7: 11 | Y7: 2 | Z7: 12.8 | AA7: =Y7/$Y$8 -> 0.18181818 | AB7: =C18 -> 0.22020725 | AC7: =AA7-AB7 -> -0.038389072 | AD7: =AB7*$Y$8 -> 2.4222798 | AE7: 17 | AF7: 16 | AG7: 32.9 | AH7: =AF7/$AF$8 -> 0.64 | AI7: =C18 -> 0.22020725 | AJ7: =AH7-AI7 -> 0.41979275 | AK7: =AI7*$AF$8 -> 5.5051813 | AL7: 33 | AM7: 8 | AN7: 41 | AO7: =AM7/$AM$8 -> 0.21052632 | AP7: =C18 -> 0.22020725 | AQ7: =AO7-AP7 -> -0.0096809381 | AR7: =AP7*$AM$8 -> 8.3678756 | AS7: 44 | AT7: 14 | AU7: 57.5 | AV7: =AT7/$AT$8 -> 0.28571429 | AW7: =C18 -> 0.22020725 | AX7: =AV7-AW7 -> 0.065507032 | AY7: =AW7*$AT$8 -> 10.790155 | AZ7: 58 | BA7: -6 | BB7: 52.8 | BC7: =BA7/$BA$8 -> -0.4 | BD7: =C18 -> 0.22020725 | BE7: =BC7-BD7 -> -0.62020725 | BF7: =BD7*$BA$8 -> 3.3031088 | BG7: 53 | BH7: 4 | BI7: 57.1 | BJ7: =BH7/$BH$8 -> 0.14285714 | BK7: =C18 -> 0.22020725 | BL7: =BJ7-BK7 -> -0.077350111 | BM7: =BK7*$BH$8 -> 6.1658031 | BN7: 57 | BO7: -5 | BP7: 52.2 | BQ7: =BO7/$BO$8 -> 0.71428571 | BR7: =C18 -> 0.22020725 | BS7: =BQ7-BR7 -> 0.49407846 | BT7: =BR7*$BO$8 -> -1.5414508 | BU7: 52 | BV7: -2 | BW7: 49.9 | BX7: =BV7/$BV$8 -> -0.038461538 | BY7: =C18 -> 0.22020725 | BZ7: =BX7-BY7 -> -0.25866879 | CA7: =BY7*$BV$8 -> 11.450777 | CB7: 50 | CC7: -4 | CD7: 46.3 | CE7: =CC7/$CC$8 -> -0.11764706 | CF7: =C18 -> 0.22020725 | CG7: =CE7-CF7 -> -0.33785431 | CH7: =CF7*$CC$8 -> 7.4870466 | CI7: 46 | CJ7: -4 | CK7: 42.6 | CL7: =CJ7/$CJ$8 -> -0.090909091 | CM7: =C18 -> 0.22020725 | CN7: =CL7-CM7 -> -0.31111634 | CO7: =CM7*$CJ$8 -> 9.6891192 | CP7: 46 | CQ7: -8 | CR7: 38.6 | CS7: =CQ7/$CQ$8 -> -0.19047619 | CT7: =C18 -> 0.22020725 | CU7: =CS7-CT7 -> -0.41068344 | CV7: =CT7*$CQ$8 -> 9.2487047 | CW7: 39 | CX7: -4 | CY7: 35.4 | CZ7: =CX7/$CX$8 -> -0.23529412 | DA7: =C18 -> 0.22020725 | DB7: =CZ7-DA7 -> -0.45550137 | DC7: =DA7*$CX$8 -> 3.7435233 | DD7: 35 | DE7: 2 | DF7: 37.3 | DG7: =DE7/$DE$8 -> -0.058823529 | DH7: =C18 -> 0.22020725 | DI7: =DG7-DH7 -> -0.27903078 | DJ7: =DH7*$DE$8 -> -7.4870466 | DK7: 37 | DL7: -1 | DM7: 36.4 | DN7: =DL7/$DL$8 -> -0.2 | DO7: =C18 -> 0.22020725 | DP7: =DN7-DO7 -> -0.42020725 | DQ7: =DO7*$DL$8 -> 1.1010363 | DR7: 36 | DS7: -3 | DT7: 33.3 | DU7: =DS7/$DS$8 -> -0.21428571 | DV7: =C18 -> 0.22020725 | DW7: =DU7-DV7 -> -0.43449297 | DX7: =DV7*$DS$8 -> 3.0829016 | DY7: 33 | DZ7: 4 | EA7: 37.6 | EB7: =DZ7/$DZ$8 -> -0.060606061 | EC7: =C18 -> 0.22020725 | ED7: =EB7-EC7 -> -0.28081331 | EE7: =EC7*$DZ$8 -> -14.533679 | EF7: 38 | EG7: 2 | EH7: 40 | EI7: =EG7/$EG$8 -> 0.2 | EJ7: =C18 -> 0.22020725 | EK7: =EI7-EJ7 -> -0.020207254 | EL7: =EJ7*$EG$8 -> 2.2020725 | EM7: 40 | EN7: -6 | EO7: 33.6 | EP7: =EN7/$EN$8 -> 0.21428571 | EQ7: =C18 -> 0.22020725 | ER7: =EP7-EQ7 -> -0.0059215396 | ES7: =EQ7*$EN$8 -> -6.1658031 | ET7: 34 | EU7: -4 | EV7: 29.6 | EW7: =EU7/$EU$8 -> 0.21052632 | EX7: =C18 -> 0.22020725 | EY7: =EW7-EX7 -> -0.0096809381 | EZ7: =EX7*$EU$8 -> -4.1839378 | FA7: 30 | FB7: 4 | FC7: 33.7 | FD7: =FB7/$FB$8 -> 0.21052632 | FE7: =C18 -> 0.22020725 | FF7: =FD7-FE7 -> -0.0096809381 | FG7: =FE7*$FB$8 -> 4.1839378 | FH7: 39 | FI7: 5 | FJ7: 43.8 | FK7: =FI7/$FI$8 -> 0.38461538 | FL7: =C18 -> 0.22020725 | FM7: =FK7-FL7 -> 0.16440813 | FN7: =FL7*$FI$8 -> 2.8626943
D8: =SUM(D5:D7) -> 14 | I8: =SUM(I5:I7) -> 14 | K8: =SUM(K5:K7) -> 35 | P8: =SUM(P5:P7) -> 19.712435 | R8: =SUM(R5:R7) -> 33 | W8: =SUM(W5:W7) -> 33 | Y8: =SUM(Y5:Y7) -> 11 | AD8: =SUM(AD5:AD7) -> 11 | AF8: =SUM(AF5:AF7) -> 25 | AK8: =SUM(AK5:AK7) -> 25 | AM8: =SUM(AM5:AM7) -> 38 | AR8: =SUM(AR5:AR7) -> 38 | AT8: =SUM(AT5:AT7) -> 49 | AY8: =SUM(AY5:AY7) -> 49 | BA8: =SUM(BA5:BA7) -> 15 | BF8: =SUM(BF5:BF7) -> 15 | BH8: =SUM(BH5:BH7) -> 28 | BM8: =SUM(BM5:BM7) -> 28 | BO8: =SUM(BO5:BO7) -> -7 | BT8: =SUM(BT5:BT7) -> -7 | BV8: =SUM(BV5:BV7) -> 52 | CA8: =SUM(CA5:CA7) -> 52 | CC8: =SUM(CC5:CC7) -> 34 | CH8: =SUM(CH5:CH7) -> 34 | CJ8: =SUM(CJ5:CJ7) -> 44 | CO8: =SUM(CO5:CO7) -> 44 | CQ8: =SUM(CQ5:CQ7) -> 42 | CV8: =SUM(CV5:CV7) -> 42 | CX8: =SUM(CX5:CX7) -> 17 | DC8: =SUM(DC5:DC7) -> 17 | DE8: =SUM(DE5:DE7) -> -34 | DJ8: =SUM(DJ5:DJ7) -> -34 | DL8: =SUM(DL5:DL7) -> 5 | DQ8: =SUM(DQ5:DQ7) -> 5 | DS8: =SUM(DS5:DS7) -> 14 | DX8: =SUM(DX5:DX7) -> 14 | DZ8: =SUM(DZ5:DZ7) -> -66 | EE8: =SUM(EE5:EE7) -> -66 | EG8: =SUM(EG5:EG7) -> 10 | EL8: =SUM(EL5:EL7) -> 10 | EN8: =SUM(EN5:EN7) -> -28 | ES8: =SUM(ES5:ES7) -> -28 | EU8: =SUM(EU5:EU7) -> -19 | EZ8: =SUM(EZ5:EZ7) -> -19 | FB8: =SUM(FB5:FB7) -> 19 | FG8: =SUM(FG5:FG7) -> 19 | FI8: =SUM(FI5:FI7) -> 13
